Workbook

Sheet Fixtures
A1: Date | B1: League | C1: Fixture | D1: Backing | E1: Proj | F1: Line | G1: Fair odds | H1: Your odds | I1: EV % | J1: Closing | K1: CLV % | L1: Corners | M1: Result | N1: Notes | O1: Stake £ | P1: _first
A2: 46259 | B2: Brazil Serie B | C2: Atletico GO v Botafogo SP | D2: Atletico GO | E2: 7.5 | F2: 6+ | G2: 1.47 | H2: 1.66 | I2: =IF(OR(G2="",H2=""),"",H2/G2-1) | K2: =IF(OR(H2="",J2=""),"",H2/J2-1) | M2: W | N2: Price drifted in: taken 1.72, now 1.66 | O2: =IF(OR(I2="",I2<=0,H2<=1),"",MIN(I2/(H2-1),Summary!$B$32)*Summary!$B$31*Summary!$B$30) | P2: =IF(B2="",0,IF(COUNTIF($B$2:B2,B2)=1,1,0))
A3: 46262 | B3: Spain La Liga | C3: Alaves v Villarreal | D3: Alaves | E3: 6.1 | F3: 5+ | G3: 1.49 | H3: 1.5 | I3: =IF(OR(G3="",H3=""),"",H3/G3-1) | K3: =IF(OR(H3="",J3=""),"",H3/J3-1) | N3: 6+ also quoted 1.90 | O3: =IF(OR(I3="",I3<=0,H3<=1),"",MIN(I3/(H3-1),Summary!$B$32)*Summary!$B$31*Summary!$B$30) | P3: =IF(B3="",0,IF(COUNTIF($B$2:B3,B3)=1,1,0))
A4: 46262 | B4: Portugal Primeira Liga | C4: Rio Ave v Sporting CP | D4: Sporting CP | E4: 6.4 | F4: 5+ | G4: 1.43 | H4: 1.22 | I4: =IF(OR(G4="",H4=""),"",H4/G4-1) | K4: =IF(OR(H4="",J4=""),"",H4/J4-1) | O4: =IF(OR(I4="",I4<=0,H4<=1),"",MIN(I4/(H4-1),Summary!$B$32)*Summary!$B$31*Summary!$B$30) | P4: =IF(B4="",0,IF(COUNTIF($B$2:B4,B4)=1,1,0))
A5: 46262 | B5: Belgium Pro League | C5: Genk v Beveren | D5: Genk | F5: 6+ | G5: 2.16 | H5: 2 | I5: =IF(OR(G5="",H5=""),"",H5/G5-1) | K5: =IF(OR(H5="",J5=""),"",H5/J5-1) | N5: No projection or line written yet | O5: =IF(OR(I5="",I5<=0,H5<=1),"",MIN(I5/(H5-1),Summary!$B$32)*Summary!$B$31*Summary!$B$30) | P5: =IF(B5="",0,IF(COUNTIF($B$2:B5,B5)=1,1,0))
A6: 46263 | B6: Italy Serie A | C6: Juventus v Parma | D6: Juventus | E6: 7.1 | F6: 6+ | G6: 1.53 | H6: 1.36 | I6: =IF(OR(G6="",H6=""),"",H6/G6-1) | K6: =IF(OR(H6="",J6=""),"",H6/J6-1) | O6: =IF(OR(I6="",I6<=0,H6<=1),"",MIN(I6/(H6-1),Summary!$B$32)*Summary!$B$31*Summary!$B$30) | P6: =IF(B6="",0,IF(COUNTIF($B$2:B6,B6)=1,1,0))
A7: 46263 | B7: Italy Serie A | C7: Fiorentina v Fros | D7: Fiorentina | E7: 8.5 | F7: 8+ | G7: 1.78 | H7: 3.75 | I7: =IF(OR(G7="",H7=""),"",H7/G7-1) | K7: =IF(OR(H7="",J7=""),"",H7/J7-1) | N7: Also 3+ FHC 1.90, 3+ SHC 1.72. Opponent conceded 9 first-half corners v Juventus last week | O7: =IF(OR(I7="",I7<=0,H7<=1),"",MIN(I7/(H7-1),Summary!$B$32)*Summary!$B$31*Summary!$B$30) | P7: =IF(B7="",0,IF(COUNTIF($B$2:B7,B7)=1,1,0))
A8: 46263 | B8: France Ligue 1 | C8: Lyon v Le Havre | D8: Lyon | E8: 6.5 | F8: 5+ | G8: 1.41 | H8: 1.28 | I8: =IF(OR(G8="",H8=""),"",H8/G8-1) | K8: =IF(OR(H8="",J8=""),"",H8/J8-1) | N8: 7+ also quoted 1.83 | O8: =IF(OR(I8="",I8<=0,H8<=1),"",MIN(I8/(H8-1),Summary!$B$32)*Summary!$B$31*Summary!$B$30) | P8: =IF(B8="",0,IF(COUNTIF($B$2:B8,B8)=1,1,0))
A9: 46263 | B9: Germany Bundesliga | C9: Borussia Dortmund v Hamburger SV | D9: Borussia Dortmund | E9: 7.2 | F9: 6+ | G9: 1.51 | H9: 1.44 | I9: =IF(OR(G9="",H9=""),"",H9/G9-1) | K9: =IF(OR(H9="",J9=""),"",H9/J9-1) | O9: =IF(OR(I9="",I9<=0,H9<=1),"",MIN(I9/(H9-1),Summary!$B$32)*Summary!$B$31*Summary!$B$30) | P9: =IF(B9="",0,IF(COUNTIF($B$2:B9,B9)=1,1,0))
A10: 46263 | B10: Germany Bundesliga | C10: RB Leipzig v Monchengladbach | D10: RB Leipzig | E10: 5.7 | F10: 5+ | G10: 1.6 | H10: 1.36 | I10: =IF(OR(G10="",H10=""),"",H10/G10-1) | K10: =IF(OR(H10="",J10=""),"",H10/J10-1) | O10: =IF(OR(I10="",I10<=0,H10<=1),"",MIN(I10/(H10-1),Summary!$B$32)*Summary!$B$31*Summary!$B$30) | P10: =IF(B10="",0,IF(COUNTIF($B$2:B10,B10)=1,1,0))
A11: 46263 | B11: Germany Bundesliga 2 | C11: Energie Cottbus v SpVgg | D11: Energie Cottbus | E11: 6.2 | F11: 5+ | G11: 1.58 | H11: 1.72 | I11: =IF(OR(G11="",H11=""),"",H11/G11-1) | K11: =IF(OR(H11="",J11=""),"",H11/J11-1) | N11: Projection revised 5.8 -> 6.2. Marked OVERS! | O11: =IF(OR(I11="",I11<=0,H11<=1),"",MIN(I11/(H11-1),Summary!$B$32)*Summary!$B$31*Summary!$B$30) | P11: =IF(B11="",0,IF(COUNTIF($B$2:B11,B11)=1,1,0))
A12: 46263 | B12: Germany Bundesliga 2 | C12: Energie Cottbus v SpVgg | D12: Over 9.5 Asian Corners | H12: 1.83 | I12: =IF(OR(G12="",H12=""),"",H12/G12-1) | K12: =IF(OR(H12="",J12=""),"",H12/J12-1) | N12: Second bet on the same fixture — no fair odds written, so no EV | O12: =IF(OR(I12="",I12<=0,H12<=1),"",MIN(I12/(H12-1),Summary!$B$32)*Summary!$B$31*Summary!$B$30) | P12: =IF(B12="",0,IF(COUNTIF($B$2:B12,B12)=1,1,0))
A13: 46263 | B13: England Championship | C13: Cardiff v Sheff Utd | D13: Cardiff | E13: 7.2 | F13: 6+ | G13: 1.51 | H13: 1.57 | I13: =IF(OR(G13="",H13=""),"",H13/G13-1) | K13: =IF(OR(H13="",J13=""),"",H13/J13-1) | N13: Cardiff 8.0 won / Sheff Utd 6.9 conceded | O13: =IF(OR(I13="",I13<=0,H13<=1),"",MIN(I13/(H13-1),Summary!$B$32)*Summary!$B$31*Summary!$B$30) | P13: =IF(B13="",0,IF(COUNTIF($B$2:B13,B13)=1,1,0))
A14: 46263 | B14: England League One | C14: Sheff Wed v Bromley | D14: Sheff Wed | E14: 7.9 | F14: 7+ | G14: 1.63 | H14: 1.9 | I14: =IF(OR(G14="",H14=""),"",H14/G14-1) | K14: =IF(OR(H14="",J14=""),"",H14/J14-1) | N14: Sheff Wed 7.5 won / Bromley 8.5 conceded | O14: =IF(OR(I14="",I14<=0,H14<=1),"",MIN(I14/(H14-1),Summary!$B$32)*Summary!$B$31*Summary!$B$30) | P14: =IF(B14="",0,IF(COUNTIF($B$2:B14,B14)=1,1,0))
A15: 46263 | B15: England League One | C15: Stockport v Wycombe | D15: Stockport | E15: 6.9 | F15: 6+ | G15: 1.6 | H15: 1.57 | I15: =IF(OR(G15="",H15=""),"",H15/G15-1) | K15: =IF(OR(H15="",J15=""),"",H15/J15-1) | N15: Stockport 6.3 won / Wycombe 5.7 conceded | O15: =IF(OR(I15="",I15<=0,H15<=1),"",MIN(I15/(H15-1),Summary!$B$32)*Summary!$B$31*Summary!$B$30) | P15: =IF(B15="",0,IF(COUNTIF($B$2:B15,B15)=1,1,0))
A16: 46263 | B16: England League One | C16: Leyton Orient v Barnsley | D16: Leyton Orient | E16: 6.1 | F16: 5+ | G16: 1.49 | H16: 1.57 | I16: =IF(OR(G16="",H16=""),"",H16/G16-1) | K16: =IF(OR(H16="",J16=""),"",H16/J16-1) | N16: Orient 4.6 won / Barnsley 6.1 conceded | O16: =IF(OR(I16="",I16<=0,H16<=1),"",MIN(I16/(H16-1),Summary!$B$32)*Summary!$B$31*Summary!$B$30) | P16: =IF(B16="",0,IF(COUNTIF($B$2:B16,B16)=1,1,0))
A17: 46263 | B17: England League Two | C17: York v Exeter | D17: Exeter | E17: 5.5 | F17: 4+ | G17: 1.36 | H17: 1.53 | I17: =IF(OR(G17="",H17=""),"",H17/G17-1) | K17: =IF(OR(H17="",J17=""),"",H17/J17-1) | N17: Date assumed 29/08. 5+ quoted 2.10, ticked. York 5.5 / Exeter 6.0 | O17: =IF(OR(I17="",I17<=0,H17<=1),"",MIN(I17/(H17-1),Summary!$B$32)*Summary!$B$31*Summary!$B$30) | P17: =IF(B17="",0,IF(COUNTIF($B$2:B17,B17)=1,1,0))
A18: 46263 | B18: England League Two | C18: Rotherham v Chesterfield | D18: Chesterfield | E18: 6.4 | F18: 5+ | G18: 1.43 | H18: 1.72 | I18: =IF(OR(G18="",H18=""),"",H18/G18-1) | K18: =IF(OR(H18="",J18=""),"",H18/J18-1) | N18: Date assumed 29/08. Rotherham 7.0 / Chesterfield 5.7 | O18: =IF(OR(I18="",I18<=0,H18<=1),"",MIN(I18/(H18-1),Summary!$B$32)*Summary!$B$31*Summary!$B$30) | P18: =IF(B18="",0,IF(COUNTIF($B$2:B18,B18)=1,1,0))
A19: 46263 | B19: England League Two | C19: Colchester v Rochdale | D19: Colchester | E19: 5.6 | F19: 5+ | G19: 1.63 | H19: 1.66 | I19: =IF(OR(G19="",H19=""),"",H19/G19-1) | K19: =IF(OR(H19="",J19=""),"",H19/J19-1) | N19: Date assumed 29/08. Colchester 5.2 / Rochdale 6.0 | O19: =IF(OR(I19="",I19<=0,H19<=1),"",MIN(I19/(H19-1),Summary!$B$32)*Summary!$B$31*Summary!$B$30) | P19: =IF(B19="",0,IF(COUNTIF($B$2:B19,B19)=1,1,0))
A20: 46263 | B20: England League Two | C20: Newport County v Tranmere | D20: Newport County | E20: 6.2 | F20: 5+ | G20: 1.47 | H20: 1.72 | I20: =IF(OR(G20="",H20=""),"",H20/G20-1) | K20: =IF(OR(H20="",J20=""),"",H20/J20-1) | N20: Date assumed 29/08. Market N/A. Newport 5.15 / Tranmere 5.9 | O20: =IF(OR(I20="",I20<=0,H20<=1),"",MIN(I20/(H20-1),Summary!$B$32)*Summary!$B$31*Summary!$B$30) | P20: =IF(B20="",0,IF(COUNTIF($B$2:B20,B20)=1,1,0))
A21: 46263 | B21: Belgium Pro League | C21: Kortrijk v Charleroi | D21: Charleroi | E21: 7.6 | F21: 7+ | G21: 1.71 | H21: 3.75 | I21: =IF(OR(G21="",H21=""),"",H21/G21-1) | K21: =IF(OR(H21="",J21=""),"",H21/J21-1) | O21: =IF(OR(I21="",I21<=0,H21<=1),"",MIN(I21/(H21-1),Summary!$B$32)*Summary!$B$31*Summary!$B$30) | P21: =IF(B21="",0,IF(COUNTIF($B$2:B21,B21)=1,1,0))
A22: 46263 | B22: Belgium Pro League | C22: Lommel v Cercle Brugge | D22: Cercle Brugge | E22: 7.7 | F22: 7+ | G22: 1.7 | H22: 1.61 | I22: =IF(OR(G22="",H22=""),"",H22/G22-1) | K22: =IF(OR(H22="",J22=""),"",H22/J22-1) | N22: Home arrow noted against Lommel | O22: =IF(OR(I22="",I22<=0,H22<=1),"",MIN(I22/(H22-1),Summary!$B$32)*Summary!$B$31*Summary!$B$30) | P22: =IF(B22="",0,IF(COUNTIF($B$2:B22,B22)=1,1,0))
A23: 46263 | B23: Belgium Pro League | C23: OH Leuven v Standard Liege | D23: Standard Liege | E23: 6.4 | F23: 5+ | G23: 1.44 | H23: 1.66 | I23: =IF(OR(G23="",H23=""),"",H23/G23-1) | K23: =IF(OR(H23="",J23=""),"",H23/J23-1) | O23: =IF(OR(I23="",I23<=0,H23<=1),"",MIN(I23/(H23-1),Summary!$B$32)*Summary!$B$31*Summary!$B$30) | P23: =IF(B23="",0,IF(COUNTIF($B$2:B23,B23)=1,1,0))
A24: 46263 | B24: Scotland Premiership | C24: Celtic v Falkirk | D24: Celtic | E24: 6.9 | F24: 6+ | G24: 1.6 | H24: 1.22 | I24: =IF(OR(G24="",H24=""),"",H24/G24-1) | K24: =IF(OR(H24="",J24=""),"",H24/J24-1) | N24: Crossed out - no value at 1.22 | O24: =IF(OR(I24="",I24<=0,H24<=1),"",MIN(I24/(H24-1),Summary!$B$32)*Summary!$B$31*Summary!$B$30) | P24: =IF(B24="",0,IF(COUNTIF($B$2:B24,B24)=1,1,0))
A25: 46263 | B25: Turkey Super Lig | C25: Galatasaray v Goztepe | D25: Galatasaray | E25: 6.7 | F25: 6+ | G25: 1.65 | H25: 1.66 | I25: =IF(OR(G25="",H25=""),"",H25/G25-1) | K25: =IF(OR(H25="",J25=""),"",H25/J25-1) | O25: =IF(OR(I25="",I25<=0,H25<=1),"",MIN(I25/(H25-1),Summary!$B$32)*Summary!$B$31*Summary!$B$30) | P25: =IF(B25="",0,IF(COUNTIF($B$2:B25,B25)=1,1,0))
A26: 46263 | B26: Japan J League | C26: Nagoya Grampus v Fagiano Okayama | E26: 5.8 | F26: 5+ | G26: 1.57 | H26: 1.66 | I26: =IF(OR(G26="",H26=""),"",H26/G26-1) | K26: =IF(OR(H26="",J26=""),"",H26/J26-1) | O26: =IF(OR(I26="",I26<=0,H26<=1),"",MIN(I26/(H26-1),Summary!$B$32)*Summary!$B$31*Summary!$B$30) | P26: =IF(B26="",0,IF(COUNTIF($B$2:B26,B26)=1,1,0))
A27: 46263 | B27: Japan J League | C27: Vissel Kobe v Cerezo Osaka | E27: 6.6 | F27: 6+ | G27: 1.69 | H27: 2.1 | I27: =IF(OR(G27="",H27=""),"",H27/G27-1) | K27: =IF(OR(H27="",J27=""),"",H27/J27-1) | N27: Vissel Kobe havent won in 4 h2hs | O27: =IF(OR(I27="",I27<=0,H27<=1),"",MIN(I27/(H27-1),Summary!$B$32)*Summary!$B$31*Summary!$B$30) | P27: =IF(B27="",0,IF(COUNTIF($B$2:B27,B27)=1,1,0))
A28: 46263 | B28: Japan J League | C28: Urawa v Yokohama | E28: 5.8 | F28: 5+ | G28: 1.58 | H28: 1.53 | I28: =IF(OR(G28="",H28=""),"",H28/G28-1) | K28: =IF(OR(H28="",J28=""),"",H28/J28-1) | O28: =IF(OR(I28="",I28<=0,H28<=1),"",MIN(I28/(H28-1),Summary!$B$32)*Summary!$B$31*Summary!$B$30) | P28: =IF(B28="",0,IF(COUNTIF($B$2:B28,B28)=1,1,0))
A29: 46264 | B29: Brazil Serie A | C29: Sao Paulo v RB Bragantino | D29: Sao Paulo | E29: 7.7 | F29: 7+ | G29: 1.68 | H29: 2.3 | I29: =IF(OR(G29="",H29=""),"",H29/G29-1) | K29: =IF(OR(H29="",J29=""),"",H29/J29-1) | O29: =IF(OR(I29="",I29<=0,H29<=1),"",MIN(I29/(H29-1),Summary!$B$32)*Summary!$B$31*Summary!$B$30) | P29: =IF(B29="",0,IF(COUNTIF($B$2:B29,B29)=1,1,0))
A30: 46264 | B30: Brazil Serie A | C30: Mirassol v Palmeiras | D30: Mirassol | E30: 6.6 | F30: 6+ | G30: 1.68 | H30: 2.25 | I30: =IF(OR(G30="",H30=""),"",H30/G30-1) | K30: =IF(OR(H30="",J30=""),"",H30/J30-1) | O30: =IF(OR(I30="",I30<=0,H30<=1),"",MIN(I30/(H30-1),Summary!$B$32)*Summary!$B$31*Summary!$B$30) | P30: =IF(B30="",0,IF(COUNTIF($B$2:B30,B30)=1,1,0))
A31: 46264 | B31: Brazil Serie A | C31: Flamengo v Botafogo | D31: Flamengo | E31: 6.1 | F31: 5+ | G31: 1.49 | H31: 1.22 | I31: =IF(OR(G31="",H31=""),"",H31/G31-1) | K31: =IF(OR(H31="",J31=""),"",H31/J31-1) | O31: =IF(OR(I31="",I31<=0,H31<=1),"",MIN(I31/(H31-1),Summary!$B$32)*Summary!$B$31*Summary!$B$30) | P31: =IF(B31="",0,IF(COUNTIF($B$2:B31,B31)=1,1,0))
A32: 46264 | B32: Brazil Serie A | C32: Gremio v Chapecoense | D32: Gremio | E32: 6.5 | F32: 5+ | G32: 1.41 | H32: 1.33 | I32: =IF(OR(G32="",H32=""),"",H32/G32-1) | K32: =IF(OR(H32="",J32=""),"",H32/J32-1) | O32: =IF(OR(I32="",I32<=0,H32<=1),"",MIN(I32/(H32-1),Summary!$B$32)*Summary!$B$31*Summary!$B$30) | P32: =IF(B32="",0,IF(COUNTIF($B$2:B32,B32)=1,1,0))
A33: 46264 | B33: England Premier League | C33: Leeds v Brentford | D33: Leeds | E33: 6.5 | F33: 6+ | G33: 1.7 | H33: 2.37 | I33: =IF(OR(G33="",H33=""),"",H33/G33-1) | K33: =IF(OR(H33="",J33=""),"",H33/J33-1) | N33: Leeds 4.3 won / Brentford 7.3 conceded | O33: =IF(OR(I33="",I33<=0,H33<=1),"",MIN(I33/(H33-1),Summary!$B$32)*Summary!$B$31*Summary!$B$30) | P33: =IF(B33="",0,IF(COUNTIF($B$2:B33,B33)=1,1,0))
A34: 46264 | B34: England Premier League | C34: Liverpool v Nottingham Forest | D34: Liverpool | E34: 7 | F34: 6+ | G34: 1.56 | H34: 1.5 | I34: =IF(OR(G34="",H34=""),"",H34/G34-1) | K34: =IF(OR(H34="",J34=""),"",H34/J34-1) | N34: Swapped round from Forest v Liverpool. Liverpool 6.9 won / Forest 6.4 conceded | O34: =IF(OR(I34="",I34<=0,H34<=1),"",MIN(I34/(H34-1),Summary!$B$32)*Summary!$B$31*Summary!$B$30) | P34: =IF(B34="",0,IF(COUNTIF($B$2:B34,B34)=1,1,0))
A35: 46264 | B35: Portugal Primeira Liga | C35: Nacional v Estrela | D35: Nacional | E35: 5.9 | F35: 5+ | G35: 1.55 | I35: =IF(OR(G35="",H35=""),"",H35/G35-1) | K35: =IF(OR(H35="",J35=""),"",H35/J35-1) | N35: Marked AWAY | O35: =IF(OR(I35="",I35<=0,H35<=1),"",MIN(I35/(H35-1),Summary!$B$32)*Summary!$B$31*Summary!$B$30) | P35: =IF(B35="",0,IF(COUNTIF($B$2:B35,B35)=1,1,0))
A36: 46264 | B36: Belgium Pro League | C36: Gent v Club Brugge | D36: Club Brugge | E36: 6.1 | F36: 5+ | G36: 1.49 | H36: 1.4 | I36: =IF(OR(G36="",H36=""),"",H36/G36-1) | K36: =IF(OR(H36="",J36=""),"",H36/J36-1) | O36: =IF(OR(I36="",I36<=0,H36<=1),"",MIN(I36/(H36-1),Summary!$B$32)*Summary!$B$31*Summary!$B$30) | P36: =IF(B36="",0,IF(COUNTIF($B$2:B36,B36)=1,1,0))
A37: 46264 | B37: Germany Bundesliga 2 | C37: St Pauli v 1. FC Kaiserslautern | D37: St Pauli | E37: 6.9 | F37: 6+ | G37: 1.58 | H37: 1.61 | I37: =IF(OR(G37="",H37=""),"",H37/G37-1) | K37: =IF(OR(H37="",J37=""),"",H37/J37-1) | O37: =IF(OR(I37="",I37<=0,H37<=1),"",MIN(I37/(H37-1),Summary!$B$32)*Summary!$B$31*Summary!$B$30) | P37: =IF(B37="",0,IF(COUNTIF($B$2:B37,B37)=1,1,0))
A38: 46264 | B38: USA MLS | C38: Minnesota v Orlando | D38: Minnesota | E38: 6.5 | F38: 5+ | G38: 1.42 | H38: 1.36 | I38: =IF(OR(G38="",H38=""),"",H38/G38-1) | K38: =IF(OR(H38="",J38=""),"",H38/J38-1) | O38: =IF(OR(I38="",I38<=0,H38<=1),"",MIN(I38/(H38-1),Summary!$B$32)*Summary!$B$31*Summary!$B$30) | P38: =IF(B38="",0,IF(COUNTIF($B$2:B38,B38)=1,1,0))
A39: 46264 | B39: USA MLS | C39: Nashville v Cincinnati | E39: 6 | F39: 5+ | G39: 1.51 | H39: 1.44 | I39: =IF(OR(G39="",H39=""),"",H39/G39-1) | K39: =IF(OR(H39="",J39=""),"",H39/J39-1) | O39: =IF(OR(I39="",I39<=0,H39<=1),"",MIN(I39/(H39-1),Summary!$B$32)*Summary!$B$31*Summary!$B$30) | P39: =IF(B39="",0,IF(COUNTIF($B$2:B39,B39)=1,1,0))
A40: 46264 | B40: USA MLS | C40: Colorado Rapids v Real Salt Lake | E40: 6.9 | F40: 6+ | G40: 1.6 | H40: 1.9 | I40: =IF(OR(G40="",H40=""),"",H40/G40-1) | K40: =IF(OR(H40="",J40=""),"",H40/J40-1) | N40: 1-0 or 2-0 in last 4 home games. under goals? | O40: =IF(OR(I40="",I40<=0,H40<=1),"",MIN(I40/(H40-1),Summary!$B$32)*Summary!$B$31*Summary!$B$30) | P40: =IF(B40="",0,IF(COUNTIF($B$2:B40,B40)=1,1,0))
...

Sheet Summary
A1: Corner ledger
A2: Every figure recalculates from the Fixtures tab. Type only in the yellow cells.
A4: Coverage
A5: Fixtures | B5: =COUNTA(Fixtures!$C$2:$C$101)
A6: Leagues | B6: =SUM(Fixtures!$P$2:$P$101)
A7: Priced up | B7: =COUNT(Fixtures!$H$2:$H$101) | C7: Rows where you've entered your odds
A8: Still to price | B8: =$B$5-$B$7 | C8: Has a fixture but no price yet
A10: Value
A11: Average EV | B11: =IFERROR(AVERAGE(Fixtures!$I$2:$I$101),"") | C11: Across priced rows only
A12: Positive EV bets | B12: =COUNTIF(Fixtures!$I$2:$I$101,">0")
A13: Negative EV bets | B13: =COUNTIF(Fixtures!$I$2:$I$101,"<0") | C13: Your reds
A14: Best EV on the card | B14: =IFERROR(MAX(Fixtures!$I$2:$I$101),"")
A15: Best EV fixture | B15: =IFERROR(INDEX(Fixtures!$C$2:$C$101,MATCH($B$14,Fixtures!$I$2:$I$101,0)),"")
A17: Closing line value
A18: Average CLV | B18: =IFERROR(AVERAGE(Fixtures!$K$2:$K$101),"needs closing prices")
A19: Beat the close | B19: =COUNTIF(Fixtures!$K$2:$K$101,">0")
A20: Beaten by the close | B20: =COUNTIF(Fixtures!$K$2:$K$101,"<0")
A22: Results
A23: Won | B23: =COUNTIF(Fixtures!$M$2:$M$101,"W")
A24: Lost | B24: =COUNTIF(Fixtures!$M$2:$M$101,"L")
A25: Void | B25: =COUNTIF(Fixtures!$M$2:$M$101,"V") | C25: Stake returned — excluded from strike rate
A26: Settled | B26: =$B$23+$B$24
A27: Strike rate | B27: =IFERROR($B$23/$B$26,"") | C27: Voids excluded
A29: Staking
A30: Bankroll (£) | B30: 1000 | C30: Drives the Stake column on Fixtures.
A31: Kelly fraction | B31: 0.25 | C31: Quarter Kelly. Full Kelly assumes your fair odds are exactly right; they are your own model's, and its edge is not yet measured, so bet a fraction of what Kelly says.
A32: Max stake (% of bank) | B32: 0.02 | C32: Hard cap, so one short-priced line cannot take the bank.
A35: How to use
A36: Yellow cells | B36: Your odds, Closing, Corners, Result on Fixtures; bankroll and staking here.
A37: EV % | B37: Your odds / Fair odds - 1. Green above zero, red below.
A38: CLV % | B38: Your odds / Closing - 1. Whether you beat the close.
A39: Result | B39: Pick W, L or V from the dropdown. The row tints green or red.
A40: Stake £ | B40: Quarter-Kelly from the EV, capped. Blank when there is no edge.
A41: Filters | B41: Row 1 has filter arrows — narrow by date or league.
A42: Example | B42: Rotherham v Chesterfield: Fair 1.43, type 1.72 into Your odds -> EV shows +20.3%.
A44: Carried over from the handwritten pages
A45: League Two dates | B45: Not written on the page — assumed Sat 29 Aug.
A46: Five undated fixtures | B46: Three Serie B, Young Boys v Basel, LASK v Altach — Date left blank.
A47: Different-line prices | B47: Where your market price was for a different line than the fair odds, it sits in Notes, not in Your odds.
A48: Fair odds | B48: Your own figures, copied as written — not recalculated.
...
