Workbook

Sheet Read me
A1: Corner board — the next 7 days
A3: Window | B3: 2026-10-01 to 2026-10-08 inclusive (kick-off dates, 77 fixtures)
A4: Built from | B4: corner-model-export.md — the site's own full data export
A5: Export generated | B5: 2026-10-01 09:57 UTC
A6: Model dispersion (NB r) | B6: 11 | C6: ← the model's own dispersion parameter (server.py NB_R). Every team-line price on every sheet reads this cell.
A7: Bet at EV of | B7: 0.05 | C7: ← BET above this edge, 'thin' between 0 and here, 'no bet' below 0.
A10: THIS WEEK IS AN INTERNATIONAL BREAK
B11: 77 fixtures fall in the window and the big European leagues are not among them: the Premier League, Bundesliga, La Liga and Serie A all resume on 9-11 October. What is here is Brazil (Série A and B), Argentina, the English League One and Two, the Dutch Eerste Divisie, Norway's 1. divisjon and two MLS games. The boards are thin because the calendar is thin, not because the model went quiet.
A13: THE FOUR BOARDS
A14: Streaks | B14: A team keeps clearing — or keeps staying under — the same line. A run and nothing about the opponent. Three types in one sheet: team over, team under, match total under. Filter the Type column.
A15: Mismatches | B15: This attack against THIS defence. About the fixture rather than the form: a side winning more corners than its league average drawn against one conceding more than its league average.
A16: Chase board | B16: This team at this venue against that defence at theirs, ordered by the backend's own chase score. A filter, not a ranking — see below.
A17: Perfect games | B17: Where a run and a favourable matchup point at the same fixture. The shortlist, not a verdict.
A19: HOW TO USE IT
B20: Type the bookmaker's decimal odds into the yellow Book column. Probability, fair odds, EV and the verdict are formulas — they fill themselves in, and they re-price if you edit a lambda.
B21: YELLOW is yours to type in. BLUE is a figure from the export — the model's, not the market's. Black is a formula and does not need touching.
B22: Check the market actually offers that line at that price before backing it. The lines here are the model's, not a bookmaker's.
A24: WHAT THE COLUMNS MEAN
A25: Bet | B25: The claim being priced. '6+ team corners' is that team's own corners; 'under 9 match corners' is the whole game. The same two characters mean different bets.
A26: λ (lambda) | B26: The model's expected corner count for that team (or the match) in that fixture, taken from the export's upcoming-fixtures list. Every price on the row comes from it, and every sheet prices the same game off the same number. The mismatch board in the export carries a lambda of its own, built from the two venue averages alone; where the two differ it is by about a tenth of a corner, and this workbook uses the fixture one.
A27: Avg | B27: On the Streaks sheet: the last-five average of whatever the streak is about — that team's own corners, or the match total.
A28: Prob | B28: The model's probability, computed on the row from λ: Negative Binomial for a team line, Poisson for a match total — the same two distributions the backend prices with.
A29: Void | B29: An under on a whole line pushes when the count lands exactly on it. Fair price is taken over settled outcomes only, and EV credits the stake back on a void. An over cannot push, so this is zero there.
A30: Fair | B30: The model's price. Beat it and there is an edge; that is all EV measures.
A31: Run / L5 | B31: Run is how many games the streak is currently at. L5 is how many of the last five cleared the line — a success rate on the exact thing claimed.
A32: Chase score | B32: λ × (0.6 + 0.4 × consistency), the backend's own formula.
A34: WHAT IS DERIVED HERE AND NOT THE SITE'S OWN OUTPUT
A35: Chase board | B35: The site measures consistency on the team's last five AT THE VENUE and requires four games there. The export carries venue averages but no venue-by-venue game list, so the L5 hits column counts the last five OVERALL. The venue averages, λ, the line and the score are the backend's arithmetic; that one column is a proxy.
A36: Perfect games | B36: The site also requires the opponent to have CONCEDED that line in at least five of their last ten at the relevant venue — a count, because an average hides the shape of it. The export carries only the average, shown here as 'Opp conc/g'. So this sheet is a looser shortlist than /perfect-games would return.
A37: Next fixture | B37: The boards in the export name a team and a league but not the game. Each row here was joined to that team's earliest fixture inside the window, from the export's own upcoming-fixtures list.
A39: WHAT THIS IS NOT
B40: Not a bet list. A fair price with no book price beside it is a lead to check.
B41: A long run is the weakest reading of a team on its own. measure_chase_board.py replayed four orderings of this board walk-forward and could not separate any of them from a shuffled control — so order the sheets by anything you like, but treat them as filters rather than as a ranking of confidence.
B42: Corner counts are real (API-Football). Bookmaker odds are yours to type; every model figure here is a fair value, not a market price.
B43: Dates are kick-off dates from the export, which does not carry kick-off times.
A45: Rows on each sheet
A46: Streaks | B46: 137
A47: Mismatches | B47: 10
A48: Chase board | B48: 106
A49: Perfect games | B49: 6

Sheet Streaks
A1: Date | B1: League | C1: Fixture | D1: Team | E1: Side | F1: Type | G1: Bet | H1: Run | I1: Longest | J1: L5 | K1: Avg | L1: λ | M1: Prob | N1: Void | O1: Fair | P1: Book | Q1: EV | R1: Verdict
A2: 46298 | B2: England League One | C2: Burton Albion v Huddersfield | D2: Huddersfield | E2: Away | F2: Team over | G2: 3+ team corners | H2: 19 | I2: 19 | J2: 5/5 | K2: 6.4 | L2: 4.32 | M2: =IFERROR(1-(EXP(GAMMALN(0+'Read me'!$B$6)-GAMMALN('Read me'!$B$6)-GAMMALN(0+1)+'Read me'!$B$6*LN('Read me'!$B$6/('Read me'!$B$6+L2))+0*LN(L2/('Read me'!$B$6+L2)))+EXP(GAMMALN(1+'Read me'!$B$6)-GAMMALN('Read me'!$B$6)-GAMMALN(1+1)+'Read me'!$B$6*LN('Read me'!$B$6/('Read me'!$B$6+L2))+1*LN(L2/('Read me'!$B$6+L2)))+EXP(GAMMALN(2+'Read me'!$B$6)-GAMMALN('Read me'!$B$6)-GAMMALN(2+1)+'Read me'!$B$6*LN('Read me'!$B$6/('Read me'!$B$6+L2))+2*LN(L2/('Read me'!$B$6+L2)))),"") | N2: 0 | O2: =IFERROR(1/M2,"") | Q2: =IF(P2="","",P2*M2-1) | R2: =IF(Q2="","awaiting price",IF(Q2>='Read me'!$B$7,"BET",IF(Q2>=0,"thin","no bet")))
A3: 46298 | B3: England League One | C3: Leyton Orient v Plymouth | D3: Plymouth | E3: Away | F3: Team over | G3: 3+ team corners | H3: 19 | I3: 19 | J3: 5/5 | K3: 5.4 | L3: 6.37 | M3: =IFERROR(1-(EXP(GAMMALN(0+'Read me'!$B$6)-GAMMALN('Read me'!$B$6)-GAMMALN(0+1)+'Read me'!$B$6*LN('Read me'!$B$6/('Read me'!$B$6+L3))+0*LN(L3/('Read me'!$B$6+L3)))+EXP(GAMMALN(1+'Read me'!$B$6)-GAMMALN('Read me'!$B$6)-GAMMALN(1+1)+'Read me'!$B$6*LN('Read me'!$B$6/('Read me'!$B$6+L3))+1*LN(L3/('Read me'!$B$6+L3)))+EXP(GAMMALN(2+'Read me'!$B$6)-GAMMALN('Read me'!$B$6)-GAMMALN(2+1)+'Read me'!$B$6*LN('Read me'!$B$6/('Read me'!$B$6+L3))+2*LN(L3/('Read me'!$B$6+L3)))),"") | N3: 0 | O3: =IFERROR(1/M3,"") | Q3: =IF(P3="","",P3*M3-1) | R3: =IF(Q3="","awaiting price",IF(Q3>='Read me'!$B$7,"BET",IF(Q3>=0,"thin","no bet")))
A4: 46298 | B4: England League Two | C4: Salford City v Fleetwood Town | D4: Salford City | E4: Home | F4: Team over | G4: 3+ team corners | H4: 18 | I4: 18 | J4: 5/5 | K4: 7.2 | L4: 6.03 | M4: =IFERROR(1-(EXP(GAMMALN(0+'Read me'!$B$6)-GAMMALN('Read me'!$B$6)-GAMMALN(0+1)+'Read me'!$B$6*LN('Read me'!$B$6/('Read me'!$B$6+L4))+0*LN(L4/('Read me'!$B$6+L4)))+EXP(GAMMALN(1+'Read me'!$B$6)-GAMMALN('Read me'!$B$6)-GAMMALN(1+1)+'Read me'!$B$6*LN('Read me'!$B$6/('Read me'!$B$6+L4))+1*LN(L4/('Read me'!$B$6+L4)))+EXP(GAMMALN(2+'Read me'!$B$6)-GAMMALN('Read me'!$B$6)-GAMMALN(2+1)+'Read me'!$B$6*LN('Read me'!$B$6/('Read me'!$B$6+L4))+2*LN(L4/('Read me'!$B$6+L4)))),"") | N4: 0 | O4: =IFERROR(1/M4,"") | Q4: =IF(P4="","",P4*M4-1) | R4: =IF(Q4="","awaiting price",IF(Q4>='Read me'!$B$7,"BET",IF(Q4>=0,"thin","no bet")))
A5: 46299 | B5: Argentina Liga Profesional | C5: Talleres Cordoba v Belgrano Cordoba | D5: Belgrano Cordoba | E5: Away | F5: Team under | G5: under 8 team corners | H5: 17 | I5: 17 | J5: 4/4 | K5: 6 | L5: 4.36 | M5: =IFERROR((EXP(GAMMALN(0+'Read me'!$B$6)-GAMMALN('Read me'!$B$6)-GAMMALN(0+1)+'Read me'!$B$6*LN('Read me'!$B$6/('Read me'!$B$6+L5))+0*LN(L5/('Read me'!$B$6+L5)))+EXP(GAMMALN(1+'Read me'!$B$6)-GAMMALN('Read me'!$B$6)-GAMMALN(1+1)+'Read me'!$B$6*LN('Read me'!$B$6/('Read me'!$B$6+L5))+1*LN(L5/('Read me'!$B$6+L5)))+EXP(GAMMALN(2+'Read me'!$B$6)-GAMMALN('Read me'!$B$6)-GAMMALN(2+1)+'Read me'!$B$6*LN('Read me'!$B$6/('Read me'!$B$6+L5))+2*LN(L5/('Read me'!$B$6+L5)))+EXP(GAMMALN(3+'Read me'!$B$6)-GAMMALN('Read me'!$B$6)-GAMMALN(3+1)+'Read me'!$B$6*LN('Read me'!$B$6/('Read me'!$B$6+L5))+3*LN(L5/('Read me'!$B$6+L5)))+EXP(GAMMALN(4+'Read me'!$B$6)-GAMMALN('Read me'!$B$6)-GAMMALN(4+1)+'Read me'!$B$6*LN('Read me'!$B$6/('Read me'!$B$6+L5))+4*LN(L5/('Read me'!$B$6+L5)))+EXP(GAMMALN(5+'Read me'!$B$6)-GAMMALN('Read me'!$B$6)-GAMMALN(5+1)+'Read me'!$B$6*LN('Read me'!$B$6/('Read me'!$B$6+L5))+5*LN(L5/('Read me'!$B$6+L5)))+EXP(GAMMALN(6+'Read me'!$B$6)-GAMMALN('Read me'!$B$6)-GAMMALN(6+1)+'Read me'!$B$6*LN('Read me'!$B$6/('Read me'!$B$6+L5))+6*LN(L5/('Read me'!$B$6+L5)))+EXP(GAMMALN(7+'Read me'!$B$6)-GAMMALN('Read me'!$B$6)-GAMMALN(7+1)+'Read me'!$B$6*LN('Read me'!$B$6/('Read me'!$B$6+L5))+7*LN(L5/('Read me'!$B$6+L5)))),"") | N5: =IFERROR(EXP(GAMMALN(8+'Read me'!$B$6)-GAMMALN('Read me'!$B$6)-GAMMALN(8+1)+'Read me'!$B$6*LN('Read me'!$B$6/('Read me'!$B$6+L5))+8*LN(L5/('Read me'!$B$6+L5))),"") | O5: =IFERROR((1-N5)/M5,"") | Q5: =IF(P5="","",P5*M5+N5-1) | R5: =IF(Q5="","awaiting price",IF(Q5>='Read me'!$B$7,"BET",IF(Q5>=0,"thin","no bet")))
A6: 46298 | B6: England League One | C6: Reading v Bradford | D6: Reading | E6: Home | F6: Team under | G6: under 7 team corners | H6: 16 | I6: 16 | J6: 4/4 | K6: 5 | L6: 5.04 | M6: =IFERROR((EXP(GAMMALN(0+'Read me'!$B$6)-GAMMALN('Read me'!$B$6)-GAMMALN(0+1)+'Read me'!$B$6*LN('Read me'!$B$6/('Read me'!$B$6+L6))+0*LN(L6/('Read me'!$B$6+L6)))+EXP(GAMMALN(1+'Read me'!$B$6)-GAMMALN('Read me'!$B$6)-GAMMALN(1+1)+'Read me'!$B$6*LN('Read me'!$B$6/('Read me'!$B$6+L6))+1*LN(L6/('Read me'!$B$6+L6)))+EXP(GAMMALN(2+'Read me'!$B$6)-GAMMALN('Read me'!$B$6)-GAMMALN(2+1)+'Read me'!$B$6*LN('Read me'!$B$6/('Read me'!$B$6+L6))+2*LN(L6/('Read me'!$B$6+L6)))+EXP(GAMMALN(3+'Read me'!$B$6)-GAMMALN('Read me'!$B$6)-GAMMALN(3+1)+'Read me'!$B$6*LN('Read me'!$B$6/('Read me'!$B$6+L6))+3*LN(L6/('Read me'!$B$6+L6)))+EXP(GAMMALN(4+'Read me'!$B$6)-GAMMALN('Read me'!$B$6)-GAMMALN(4+1)+'Read me'!$B$6*LN('Read me'!$B$6/('Read me'!$B$6+L6))+4*LN(L6/('Read me'!$B$6+L6)))+EXP(GAMMALN(5+'Read me'!$B$6)-GAMMALN('Read me'!$B$6)-GAMMALN(5+1)+'Read me'!$B$6*LN('Read me'!$B$6/('Read me'!$B$6+L6))+5*LN(L6/('Read me'!$B$6+L6)))+EXP(GAMMALN(6+'Read me'!$B$6)-GAMMALN('Read me'!$B$6)-GAMMALN(6+1)+'Read me'!$B$6*LN('Read me'!$B$6/('Read me'!$B$6+L6))+6*LN(L6/('Read me'!$B$6+L6)))),"") | N6: =IFERROR(EXP(GAMMALN(7+'Read me'!$B$6)-GAMMALN('Read me'!$B$6)-GAMMALN(7+1)+'Read me'!$B$6*LN('Read me'!$B$6/('Read me'!$B$6+L6))+7*LN(L6/('Read me'!$B$6+L6))),"") | O6: =IFERROR((1-N6)/M6,"") | Q6: =IF(P6="","",P6*M6+N6-1) | R6: =IF(Q6="","awaiting price",IF(Q6>='Read me'!$B$7,"BET",IF(Q6>=0,"thin","no bet")))
A7: 46302 | B7: Brazil Série A | C7: Vitoria v Chapecoense-sc | D7: Chapecoense-sc | E7: Away | F7: Team under | G7: under 7 team corners | H7: 16 | I7: 16 | J7: 3/3 | K7: 4.4 | L7: 3.07 | M7: =IFERROR((EXP(GAMMALN(0+'Read me'!$B$6)-GAMMALN('Read me'!$B$6)-GAMMALN(0+1)+'Read me'!$B$6*LN('Read me'!$B$6/('Read me'!$B$6+L7))+0*LN(L7/('Read me'!$B$6+L7)))+EXP(GAMMALN(1+'Read me'!$B$6)-GAMMALN('Read me'!$B$6)-GAMMALN(1+1)+'Read me'!$B$6*LN('Read me'!$B$6/('Read me'!$B$6+L7))+1*LN(L7/('Read me'!$B$6+L7)))+EXP(GAMMALN(2+'Read me'!$B$6)-GAMMALN('Read me'!$B$6)-GAMMALN(2+1)+'Read me'!$B$6*LN('Read me'!$B$6/('Read me'!$B$6+L7))+2*LN(L7/('Read me'!$B$6+L7)))+EXP(GAMMALN(3+'Read me'!$B$6)-GAMMALN('Read me'!$B$6)-GAMMALN(3+1)+'Read me'!$B$6*LN('Read me'!$B$6/('Read me'!$B$6+L7))+3*LN(L7/('Read me'!$B$6+L7)))+EXP(GAMMALN(4+'Read me'!$B$6)-GAMMALN('Read me'!$B$6)-GAMMALN(4+1)+'Read me'!$B$6*LN('Read me'!$B$6/('Read me'!$B$6+L7))+4*LN(L7/('Read me'!$B$6+L7)))+EXP(GAMMALN(5+'Read me'!$B$6)-GAMMALN('Read me'!$B$6)-GAMMALN(5+1)+'Read me'!$B$6*LN('Read me'!$B$6/('Read me'!$B$6+L7))+5*LN(L7/('Read me'!$B$6+L7)))+EXP(GAMMALN(6+'Read me'!$B$6)-GAMMALN('Read me'!$B$6)-GAMMALN(6+1)+'Read me'!$B$6*LN('Read me'!$B$6/('Read me'!$B$6+L7))+6*LN(L7/('Read me'!$B$6+L7)))),"") | N7: =IFERROR(EXP(GAMMALN(7+'Read me'!$B$6)-GAMMALN('Read me'!$B$6)-GAMMALN(7+1)+'Read me'!$B$6*LN('Read me'!$B$6/('Read me'!$B$6+L7))+7*LN(L7/('Read me'!$B$6+L7))),"") | O7: =IFERROR((1-N7)/M7,"") | Q7: =IF(P7="","",P7*M7+N7-1) | R7: =IF(Q7="","awaiting price",IF(Q7>='Read me'!$B$7,"BET",IF(Q7>=0,"thin","no bet")))
A8: 46299 | B8: Argentina Liga Profesional | C8: Huracan v Aldosivi | D8: Aldosivi | E8: Away | F8: Team under | G8: under 8 team corners | H8: 15 | I8: 15 | J8: 4/4 | K8: 4.8 | L8: 3.94 | M8: =IFERROR((EXP(GAMMALN(0+'Read me'!$B$6)-GAMMALN('Read me'!$B$6)-GAMMALN(0+1)+'Read me'!$B$6*LN('Read me'!$B$6/('Read me'!$B$6+L8))+0*LN(L8/('Read me'!$B$6+L8)))+EXP(GAMMALN(1+'Read me'!$B$6)-GAMMALN('Read me'!$B$6)-GAMMALN(1+1)+'Read me'!$B$6*LN('Read me'!$B$6/('Read me'!$B$6+L8))+1*LN(L8/('Read me'!$B$6+L8)))+EXP(GAMMALN(2+'Read me'!$B$6)-GAMMALN('Read me'!$B$6)-GAMMALN(2+1)+'Read me'!$B$6*LN('Read me'!$B$6/('Read me'!$B$6+L8))+2*LN(L8/('Read me'!$B$6+L8)))+EXP(GAMMALN(3+'Read me'!$B$6)-GAMMALN('Read me'!$B$6)-GAMMALN(3+1)+'Read me'!$B$6*LN('Read me'!$B$6/('Read me'!$B$6+L8))+3*LN(L8/('Read me'!$B$6+L8)))+EXP(GAMMALN(4+'Read me'!$B$6)-GAMMALN('Read me'!$B$6)-GAMMALN(4+1)+'Read me'!$B$6*LN('Read me'!$B$6/('Read me'!$B$6+L8))+4*LN(L8/('Read me'!$B$6+L8)))+EXP(GAMMALN(5+'Read me'!$B$6)-GAMMALN('Read me'!$B$6)-GAMMALN(5+1)+'Read me'!$B$6*LN('Read me'!$B$6/('Read me'!$B$6+L8))+5*LN(L8/('Read me'!$B$6+L8)))+EXP(GAMMALN(6+'Read me'!$B$6)-GAMMALN('Read me'!$B$6)-GAMMALN(6+1)+'Read me'!$B$6*LN('Read me'!$B$6/('Read me'!$B$6+L8))+6*LN(L8/('Read me'!$B$6+L8)))+EXP(GAMMALN(7+'Read me'!$B$6)-GAMMALN('Read me'!$B$6)-GAMMALN(7+1)+'Read me'!$B$6*LN('Read me'!$B$6/('Read me'!$B$6+L8))+7*LN(L8/('Read me'!$B$6+L8)))),"") | N8: =IFERROR(EXP(GAMMALN(8+'Read me'!$B$6)-GAMMALN('Read me'!$B$6)-GAMMALN(8+1)+'Read me'!$B$6*LN('Read me'!$B$6/('Read me'!$B$6+L8))+8*LN(L8/('Read me'!$B$6+L8))),"") | O8: =IFERROR((1-N8)/M8,"") | Q8: =IF(P8="","",P8*M8+N8-1) | R8: =IF(Q8="","awaiting price",IF(Q8>='Read me'!$B$7,"BET",IF(Q8>=0,"thin","no bet")))
A9: 46300 | B9: Argentina Liga Profesional | C9: Estudiantes L.P. v Gimnasia M. | D9: Estudiantes L.P. | E9: Home | F9: Team under | G9: under 8 team corners | H9: 15 | I9: 15 | J9: 4/4 | K9: 4.4 | L9: 4.77 | M9: =IFERROR((EXP(GAMMALN(0+'Read me'!$B$6)-GAMMALN('Read me'!$B$6)-GAMMALN(0+1)+'Read me'!$B$6*LN('Read me'!$B$6/('Read me'!$B$6+L9))+0*LN(L9/('Read me'!$B$6+L9)))+EXP(GAMMALN(1+'Read me'!$B$6)-GAMMALN('Read me'!$B$6)-GAMMALN(1+1)+'Read me'!$B$6*LN('Read me'!$B$6/('Read me'!$B$6+L9))+1*LN(L9/('Read me'!$B$6+L9)))+EXP(GAMMALN(2+'Read me'!$B$6)-GAMMALN('Read me'!$B$6)-GAMMALN(2+1)+'Read me'!$B$6*LN('Read me'!$B$6/('Read me'!$B$6+L9))+2*LN(L9/('Read me'!$B$6+L9)))+EXP(GAMMALN(3+'Read me'!$B$6)-GAMMALN('Read me'!$B$6)-GAMMALN(3+1)+'Read me'!$B$6*LN('Read me'!$B$6/('Read me'!$B$6+L9))+3*LN(L9/('Read me'!$B$6+L9)))+EXP(GAMMALN(4+'Read me'!$B$6)-GAMMALN('Read me'!$B$6)-GAMMALN(4+1)+'Read me'!$B$6*LN('Read me'!$B$6/('Read me'!$B$6+L9))+4*LN(L9/('Read me'!$B$6+L9)))+EXP(GAMMALN(5+'Read me'!$B$6)-GAMMALN('Read me'!$B$6)-GAMMALN(5+1)+'Read me'!$B$6*LN('Read me'!$B$6/('Read me'!$B$6+L9))+5*LN(L9/('Read me'!$B$6+L9)))+EXP(GAMMALN(6+'Read me'!$B$6)-GAMMALN('Read me'!$B$6)-GAMMALN(6+1)+'Read me'!$B$6*LN('Read me'!$B$6/('Read me'!$B$6+L9))+6*LN(L9/('Read me'!$B$6+L9)))+EXP(GAMMALN(7+'Read me'!$B$6)-GAMMALN('Read me'!$B$6)-GAMMALN(7+1)+'Read me'!$B$6*LN('Read me'!$B$6/('Read me'!$B$6+L9))+7*LN(L9/('Read me'!$B$6+L9)))),"") | N9: =IFERROR(EXP(GAMMALN(8+'Read me'!$B$6)-GAMMALN('Read me'!$B$6)-GAMMALN(8+1)+'Read me'!$B$6*LN('Read me'!$B$6/('Read me'!$B$6+L9))+8*LN(L9/('Read me'!$B$6+L9))),"") | O9: =IFERROR((1-N9)/M9,"") | Q9: =IF(P9="","",P9*M9+N9-1) | R9: =IF(Q9="","awaiting price",IF(Q9>='Read me'!$B$7,"BET",IF(Q9>=0,"thin","no bet")))
A10: 46297 | B10: Brazil Série B | C10: Londrina v Criciuma | D10: Criciuma | E10: Away | F10: Team over | G10: 4+ team corners | H10: 14 | I10: 14 | J10: 5/5 | K10: 8.2 | L10: 5.81 | M10: =IFERROR(1-(EXP(GAMMALN(0+'Read me'!$B$6)-GAMMALN('Read me'!$B$6)-GAMMALN(0+1)+'Read me'!$B$6*LN('Read me'!$B$6/('Read me'!$B$6+L10))+0*LN(L10/('Read me'!$B$6+L10)))+EXP(GAMMALN(1+'Read me'!$B$6)-GAMMALN('Read me'!$B$6)-GAMMALN(1+1)+'Read me'!$B$6*LN('Read me'!$B$6/('Read me'!$B$6+L10))+1*LN(L10/('Read me'!$B$6+L10)))+EXP(GAMMALN(2+'Read me'!$B$6)-GAMMALN('Read me'!$B$6)-GAMMALN(2+1)+'Read me'!$B$6*LN('Read me'!$B$6/('Read me'!$B$6+L10))+2*LN(L10/('Read me'!$B$6+L10)))+EXP(GAMMALN(3+'Read me'!$B$6)-GAMMALN('Read me'!$B$6)-GAMMALN(3+1)+'Read me'!$B$6*LN('Read me'!$B$6/('Read me'!$B$6+L10))+3*LN(L10/('Read me'!$B$6+L10)))),"") | N10: 0 | O10: =IFERROR(1/M10,"") | Q10: =IF(P10="","",P10*M10-1) | R10: =IF(Q10="","awaiting price",IF(Q10>='Read me'!$B$7,"BET",IF(Q10>=0,"thin","no bet")))
A11: 46298 | B11: England League Two | C11: Grimsby v Shrewsbury | D11: Grimsby | E11: Home | F11: Team over | G11: 3+ team corners | H11: 14 | I11: 14 | J11: 5/5 | K11: 7 | L11: 5.87 | M11: =IFERROR(1-(EXP(GAMMALN(0+'Read me'!$B$6)-GAMMALN('Read me'!$B$6)-GAMMALN(0+1)+'Read me'!$B$6*LN('Read me'!$B$6/('Read me'!$B$6+L11))+0*LN(L11/('Read me'!$B$6+L11)))+EXP(GAMMALN(1+'Read me'!$B$6)-GAMMALN('Read me'!$B$6)-GAMMALN(1+1)+'Read me'!$B$6*LN('Read me'!$B$6/('Read me'!$B$6+L11))+1*LN(L11/('Read me'!$B$6+L11)))+EXP(GAMMALN(2+'Read me'!$B$6)-GAMMALN('Read me'!$B$6)-GAMMALN(2+1)+'Read me'!$B$6*LN('Read me'!$B$6/('Read me'!$B$6+L11))+2*LN(L11/('Read me'!$B$6+L11)))),"") | N11: 0 | O11: =IFERROR(1/M11,"") | Q11: =IF(P11="","",P11*M11-1) | R11: =IF(Q11="","awaiting price",IF(Q11>='Read me'!$B$7,"BET",IF(Q11>=0,"thin","no bet")))
A12: 46298 | B12: Argentina Liga Profesional | C12: Atletico Tucuman v Barracas Central | D12: Barracas Central | E12: Away | F12: Team under | G12: under 7 team corners | H12: 14 | I12: 14 | J12: 4/4 | K12: 5 | L12: 3.34 | M12: =IFERROR((EXP(GAMMALN(0+'Read me'!$B$6)-GAMMALN('Read me'!$B$6)-GAMMALN(0+1)+'Read me'!$B$6*LN('Read me'!$B$6/('Read me'!$B$6+L12))+0*LN(L12/('Read me'!$B$6+L12)))+EXP(GAMMALN(1+'Read me'!$B$6)-GAMMALN('Read me'!$B$6)-GAMMALN(1+1)+'Read me'!$B$6*LN('Read me'!$B$6/('Read me'!$B$6+L12))+1*LN(L12/('Read me'!$B$6+L12)))+EXP(GAMMALN(2+'Read me'!$B$6)-GAMMALN('Read me'!$B$6)-GAMMALN(2+1)+'Read me'!$B$6*LN('Read me'!$B$6/('Read me'!$B$6+L12))+2*LN(L12/('Read me'!$B$6+L12)))+EXP(GAMMALN(3+'Read me'!$B$6)-GAMMALN('Read me'!$B$6)-GAMMALN(3+1)+'Read me'!$B$6*LN('Read me'!$B$6/('Read me'!$B$6+L12))+3*LN(L12/('Read me'!$B$6+L12)))+EXP(GAMMALN(4+'Read me'!$B$6)-GAMMALN('Read me'!$B$6)-GAMMALN(4+1)+'Read me'!$B$6*LN('Read me'!$B$6/('Read me'!$B$6+L12))+4*LN(L12/('Read me'!$B$6+L12)))+EXP(GAMMALN(5+'Read me'!$B$6)-GAMMALN('Read me'!$B$6)-GAMMALN(5+1)+'Read me'!$B$6*LN('Read me'!$B$6/('Read me'!$B$6+L12))+5*LN(L12/('Read me'!$B$6+L12)))+EXP(GAMMALN(6+'Read me'!$B$6)-GAMMALN('Read me'!$B$6)-GAMMALN(6+1)+'Read me'!$B$6*LN('Read me'!$B$6/('Read me'!$B$6+L12))+6*LN(L12/('Read me'!$B$6+L12)))),"") | N12: =IFERROR(EXP(GAMMALN(7+'Read me'!$B$6)-GAMMALN('Read me'!$B$6)-GAMMALN(7+1)+'Read me'!$B$6*LN('Read me'!$B$6/('Read me'!$B$6+L12))+7*LN(L12/('Read me'!$B$6+L12))),"") | O12: =IFERROR((1-N12)/M12,"") | Q12: =IF(P12="","",P12*M12+N12-1) | R12: =IF(Q12="","awaiting price",IF(Q12>='Read me'!$B$7,"BET",IF(Q12>=0,"thin","no bet")))
A13: 46298 | B13: Argentina Liga Profesional | C13: Atletico Tucuman v Barracas Central | D13: Barracas Central | E13: Away | F13: Match under | G13: under 12 match corners | H13: 14 | I13: 14 | J13: 4/4 | K13: 8.4 | L13: 7.56 | M13: =IFERROR(POISSON(12-1,L13,TRUE),"") | N13: =IFERROR(POISSON(12,L13,FALSE),"") | O13: =IFERROR((1-N13)/M13,"") | Q13: =IF(P13="","",P13*M13+N13-1) | R13: =IF(Q13="","awaiting price",IF(Q13>='Read me'!$B$7,"BET",IF(Q13>=0,"thin","no bet")))
A14: 46297 | B14: Brazil Série B | C14: Novorizontino v Goias | D14: Novorizontino | E14: Home | F14: Team over | G14: 4+ team corners | H14: 13 | I14: 13 | J14: 5/5 | K14: 8 | L14: 7.32 | M14: =IFERROR(1-(EXP(GAMMALN(0+'Read me'!$B$6)-GAMMALN('Read me'!$B$6)-GAMMALN(0+1)+'Read me'!$B$6*LN('Read me'!$B$6/('Read me'!$B$6+L14))+0*LN(L14/('Read me'!$B$6+L14)))+EXP(GAMMALN(1+'Read me'!$B$6)-GAMMALN('Read me'!$B$6)-GAMMALN(1+1)+'Read me'!$B$6*LN('Read me'!$B$6/('Read me'!$B$6+L14))+1*LN(L14/('Read me'!$B$6+L14)))+EXP(GAMMALN(2+'Read me'!$B$6)-GAMMALN('Read me'!$B$6)-GAMMALN(2+1)+'Read me'!$B$6*LN('Read me'!$B$6/('Read me'!$B$6+L14))+2*LN(L14/('Read me'!$B$6+L14)))+EXP(GAMMALN(3+'Read me'!$B$6)-GAMMALN('Read me'!$B$6)-GAMMALN(3+1)+'Read me'!$B$6*LN('Read me'!$B$6/('Read me'!$B$6+L14))+3*LN(L14/('Read me'!$B$6+L14)))),"") | N14: 0 | O14: =IFERROR(1/M14,"") | Q14: =IF(P14="","",P14*M14-1) | R14: =IF(Q14="","awaiting price",IF(Q14>='Read me'!$B$7,"BET",IF(Q14>=0,"thin","no bet")))
A15: 46298 | B15: England League One | C15: Reading v Bradford | D15: Bradford | E15: Away | F15: Team over | G15: 3+ team corners | H15: 13 | I15: 13 | J15: 5/5 | K15: 5.8 | L15: 5.2 | M15: =IFERROR(1-(EXP(GAMMALN(0+'Read me'!$B$6)-GAMMALN('Read me'!$B$6)-GAMMALN(0+1)+'Read me'!$B$6*LN('Read me'!$B$6/('Read me'!$B$6+L15))+0*LN(L15/('Read me'!$B$6+L15)))+EXP(GAMMALN(1+'Read me'!$B$6)-GAMMALN('Read me'!$B$6)-GAMMALN(1+1)+'Read me'!$B$6*LN('Read me'!$B$6/('Read me'!$B$6+L15))+1*LN(L15/('Read me'!$B$6+L15)))+EXP(GAMMALN(2+'Read me'!$B$6)-GAMMALN('Read me'!$B$6)-GAMMALN(2+1)+'Read me'!$B$6*LN('Read me'!$B$6/('Read me'!$B$6+L15))+2*LN(L15/('Read me'!$B$6+L15)))),"") | N15: 0 | O15: =IFERROR(1/M15,"") | Q15: =IF(P15="","",P15*M15-1) | R15: =IF(Q15="","awaiting price",IF(Q15>='Read me'!$B$7,"BET",IF(Q15>=0,"thin","no bet")))
A16: 46298 | B16: Netherlands Eerste Divisie | C16: Almere City FC v FC Volendam | D16: Almere City FC | E16: Home | F16: Team over | G16: 3+ team corners | H16: 13 | I16: 13 | J16: 5/5 | K16: 5.2 | L16: 5.63 | M16: =IFERROR(1-(EXP(GAMMALN(0+'Read me'!$B$6)-GAMMALN('Read me'!$B$6)-GAMMALN(0+1)+'Read me'!$B$6*LN('Read me'!$B$6/('Read me'!$B$6+L16))+0*LN(L16/('Read me'!$B$6+L16)))+EXP(GAMMALN(1+'Read me'!$B$6)-GAMMALN('Read me'!$B$6)-GAMMALN(1+1)+'Read me'!$B$6*LN('Read me'!$B$6/('Read me'!$B$6+L16))+1*LN(L16/('Read me'!$B$6+L16)))+EXP(GAMMALN(2+'Read me'!$B$6)-GAMMALN('Read me'!$B$6)-GAMMALN(2+1)+'Read me'!$B$6*LN('Read me'!$B$6/('Read me'!$B$6+L16))+2*LN(L16/('Read me'!$B$6+L16)))),"") | N16: 0 | O16: =IFERROR(1/M16,"") | Q16: =IF(P16="","",P16*M16-1) | R16: =IF(Q16="","awaiting price",IF(Q16>='Read me'!$B$7,"BET",IF(Q16>=0,"thin","no bet")))
A17: 46298 | B17: Argentina Liga Profesional | C17: Newells Old Boys v Lanus | D17: Newells Old Boys | E17: Home | F17: Team under | G17: under 8 team corners | H17: 13 | I17: 13 | J17: 4/4 | K17: 3.4 | L17: 5.32 | M17: =IFERROR((EXP(GAMMALN(0+'Read me'!$B$6)-GAMMALN('Read me'!$B$6)-GAMMALN(0+1)+'Read me'!$B$6*LN('Read me'!$B$6/('Read me'!$B$6+L17))+0*LN(L17/('Read me'!$B$6+L17)))+EXP(GAMMALN(1+'Read me'!$B$6)-GAMMALN('Read me'!$B$6)-GAMMALN(1+1)+'Read me'!$B$6*LN('Read me'!$B$6/('Read me'!$B$6+L17))+1*LN(L17/('Read me'!$B$6+L17)))+EXP(GAMMALN(2+'Read me'!$B$6)-GAMMALN('Read me'!$B$6)-GAMMALN(2+1)+'Read me'!$B$6*LN('Read me'!$B$6/('Read me'!$B$6+L17))+2*LN(L17/('Read me'!$B$6+L17)))+EXP(GAMMALN(3+'Read me'!$B$6)-GAMMALN('Read me'!$B$6)-GAMMALN(3+1)+'Read me'!$B$6*LN('Read me'!$B$6/('Read me'!$B$6+L17))+3*LN(L17/('Read me'!$B$6+L17)))+EXP(GAMMALN(4+'Read me'!$B$6)-GAMMALN('Read me'!$B$6)-GAMMALN(4+1)+'Read me'!$B$6*LN('Read me'!$B$6/('Read me'!$B$6+L17))+4*LN(L17/('Read me'!$B$6+L17)))+EXP(GAMMALN(5+'Read me'!$B$6)-GAMMALN('Read me'!$B$6)-GAMMALN(5+1)+'Read me'!$B$6*LN('Read me'!$B$6/('Read me'!$B$6+L17))+5*LN(L17/('Read me'!$B$6+L17)))+EXP(GAMMALN(6+'Read me'!$B$6)-GAMMALN('Read me'!$B$6)-GAMMALN(6+1)+'Read me'!$B$6*LN('Read me'!$B$6/('Read me'!$B$6+L17))+6*LN(L17/('Read me'!$B$6+L17)))+EXP(GAMMALN(7+'Read me'!$B$6)-GAMMALN('Read me'!$B$6)-GAMMALN(7+1)+'Read me'!$B$6*LN('Read me'!$B$6/('Read me'!$B$6+L17))+7*LN(L17/('Read me'!$B$6+L17)))),"") | N17: =IFERROR(EXP(GAMMALN(8+'Read me'!$B$6)-GAMMALN('Read me'!$B$6)-GAMMALN(8+1)+'Read me'!$B$6*LN('Read me'!$B$6/('Read me'!$B$6+L17))+8*LN(L17/('Read me'!$B$6+L17))),"") | O17: =IFERROR((1-N17)/M17,"") | Q17: =IF(P17="","",P17*M17+N17-1) | R17: =IF(Q17="","awaiting price",IF(Q17>='Read me'!$B$7,"BET",IF(Q17>=0,"thin","no bet")))
A18: 46298 | B18: England League Two | C18: Walsall v Crawley Town | D18: Crawley Town | E18: Away | F18: Team under | G18: under 8 team corners | H18: 13 | I18: 13 | J18: 4/4 | K18: 4.8 | L18: 4.34 | M18: =IFERROR((EXP(GAMMALN(0+'Read me'!$B$6)-GAMMALN('Read me'!$B$6)-GAMMALN(0+1)+'Read me'!$B$6*LN('Read me'!$B$6/('Read me'!$B$6+L18))+0*LN(L18/('Read me'!$B$6+L18)))+EXP(GAMMALN(1+'Read me'!$B$6)-GAMMALN('Read me'!$B$6)-GAMMALN(1+1)+'Read me'!$B$6*LN('Read me'!$B$6/('Read me'!$B$6+L18))+1*LN(L18/('Read me'!$B$6+L18)))+EXP(GAMMALN(2+'Read me'!$B$6)-GAMMALN('Read me'!$B$6)-GAMMALN(2+1)+'Read me'!$B$6*LN('Read me'!$B$6/('Read me'!$B$6+L18))+2*LN(L18/('Read me'!$B$6+L18)))+EXP(GAMMALN(3+'Read me'!$B$6)-GAMMALN('Read me'!$B$6)-GAMMALN(3+1)+'Read me'!$B$6*LN('Read me'!$B$6/('Read me'!$B$6+L18))+3*LN(L18/('Read me'!$B$6+L18)))+EXP(GAMMALN(4+'Read me'!$B$6)-GAMMALN('Read me'!$B$6)-GAMMALN(4+1)+'Read me'!$B$6*LN('Read me'!$B$6/('Read me'!$B$6+L18))+4*LN(L18/('Read me'!$B$6+L18)))+EXP(GAMMALN(5+'Read me'!$B$6)-GAMMALN('Read me'!$B$6)-GAMMALN(5+1)+'Read me'!$B$6*LN('Read me'!$B$6/('Read me'!$B$6+L18))+5*LN(L18/('Read me'!$B$6+L18)))+EXP(GAMMALN(6+'Read me'!$B$6)-GAMMALN('Read me'!$B$6)-GAMMALN(6+1)+'Read me'!$B$6*LN('Read me'!$B$6/('Read me'!$B$6+L18))+6*LN(L18/('Read me'!$B$6+L18)))+EXP(GAMMALN(7+'Read me'!$B$6)-GAMMALN('Read me'!$B$6)-GAMMALN(7+1)+'Read me'!$B$6*LN('Read me'!$B$6/('Read me'!$B$6+L18))+7*LN(L18/('Read me'!$B$6+L18)))),"") | N18: =IFERROR(EXP(GAMMALN(8+'Read me'!$B$6)-GAMMALN('Read me'!$B$6)-GAMMALN(8+1)+'Read me'!$B$6*LN('Read me'!$B$6/('Read me'!$B$6+L18))+8*LN(L18/('Read me'!$B$6+L18))),"") | O18: =IFERROR((1-N18)/M18,"") | Q18: =IF(P18="","",P18*M18+N18-1) | R18: =IF(Q18="","awaiting price",IF(Q18>='Read me'!$B$7,"BET",IF(Q18>=0,"thin","no bet")))
A19: 46300 | B19: Argentina Liga Profesional | C19: Estudiantes de Rio Cuarto v Racing Club | D19: Racing Club | E19: Away | F19: Team under | G19: under 7 team corners | H19: 13 | I19: 13 | J19: 4/4 | K19: 4.2 | L19: 3.88 | M19: =IFERROR((EXP(GAMMALN(0+'Read me'!$B$6)-GAMMALN('Read me'!$B$6)-GAMMALN(0+1)+'Read me'!$B$6*LN('Read me'!$B$6/('Read me'!$B$6+L19))+0*LN(L19/('Read me'!$B$6+L19)))+EXP(GAMMALN(1+'Read me'!$B$6)-GAMMALN('Read me'!$B$6)-GAMMALN(1+1)+'Read me'!$B$6*LN('Read me'!$B$6/('Read me'!$B$6+L19))+1*LN(L19/('Read me'!$B$6+L19)))+EXP(GAMMALN(2+'Read me'!$B$6)-GAMMALN('Read me'!$B$6)-GAMMALN(2+1)+'Read me'!$B$6*LN('Read me'!$B$6/('Read me'!$B$6+L19))+2*LN(L19/('Read me'!$B$6+L19)))+EXP(GAMMALN(3+'Read me'!$B$6)-GAMMALN('Read me'!$B$6)-GAMMALN(3+1)+'Read me'!$B$6*LN('Read me'!$B$6/('Read me'!$B$6+L19))+3*LN(L19/('Read me'!$B$6+L19)))+EXP(GAMMALN(4+'Read me'!$B$6)-GAMMALN('Read me'!$B$6)-GAMMALN(4+1)+'Read me'!$B$6*LN('Read me'!$B$6/('Read me'!$B$6+L19))+4*LN(L19/('Read me'!$B$6+L19)))+EXP(GAMMALN(5+'Read me'!$B$6)-GAMMALN('Read me'!$B$6)-GAMMALN(5+1)+'Read me'!$B$6*LN('Read me'!$B$6/('Read me'!$B$6+L19))+5*LN(L19/('Read me'!$B$6+L19)))+EXP(GAMMALN(6+'Read me'!$B$6)-GAMMALN('Read me'!$B$6)-GAMMALN(6+1)+'Read me'!$B$6*LN('Read me'!$B$6/('Read me'!$B$6+L19))+6*LN(L19/('Read me'!$B$6+L19)))),"") | N19: =IFERROR(EXP(GAMMALN(7+'Read me'!$B$6)-GAMMALN('Read me'!$B$6)-GAMMALN(7+1)+'Read me'!$B$6*LN('Read me'!$B$6/('Read me'!$B$6+L19))+7*LN(L19/('Read me'!$B$6+L19))),"") | O19: =IFERROR((1-N19)/M19,"") | Q19: =IF(P19="","",P19*M19+N19-1) | R19: =IF(Q19="","awaiting price",IF(Q19>='Read me'!$B$7,"BET",IF(Q19>=0,"thin","no bet")))
A20: 46298 | B20: England League Two | C20: Gillingham v Newport County | D20: Gillingham | E20: Home | F20: Team under | G20: under 6 team corners | H20: 12 | I20: 12 | J20: 4/4 | K20: 3.4 | L20: 5.3 | M20: =IFERROR((EXP(GAMMALN(0+'Read me'!$B$6)-GAMMALN('Read me'!$B$6)-GAMMALN(0+1)+'Read me'!$B$6*LN('Read me'!$B$6/('Read me'!$B$6+L20))+0*LN(L20/('Read me'!$B$6+L20)))+EXP(GAMMALN(1+'Read me'!$B$6)-GAMMALN('Read me'!$B$6)-GAMMALN(1+1)+'Read me'!$B$6*LN('Read me'!$B$6/('Read me'!$B$6+L20))+1*LN(L20/('Read me'!$B$6+L20)))+EXP(GAMMALN(2+'Read me'!$B$6)-GAMMALN('Read me'!$B$6)-GAMMALN(2+1)+'Read me'!$B$6*LN('Read me'!$B$6/('Read me'!$B$6+L20))+2*LN(L20/('Read me'!$B$6+L20)))+EXP(GAMMALN(3+'Read me'!$B$6)-GAMMALN('Read me'!$B$6)-GAMMALN(3+1)+'Read me'!$B$6*LN('Read me'!$B$6/('Read me'!$B$6+L20))+3*LN(L20/('Read me'!$B$6+L20)))+EXP(GAMMALN(4+'Read me'!$B$6)-GAMMALN('Read me'!$B$6)-GAMMALN(4+1)+'Read me'!$B$6*LN('Read me'!$B$6/('Read me'!$B$6+L20))+4*LN(L20/('Read me'!$B$6+L20)))+EXP(GAMMALN(5+'Read me'!$B$6)-GAMMALN('Read me'!$B$6)-GAMMALN(5+1)+'Read me'!$B$6*LN('Read me'!$B$6/('Read me'!$B$6+L20))+5*LN(L20/('Read me'!$B$6+L20)))),"") | N20: =IFERROR(EXP(GAMMALN(6+'Read me'!$B$6)-GAMMALN('Read me'!$B$6)-GAMMALN(6+1)+'Read me'!$B$6*LN('Read me'!$B$6/('Read me'!$B$6+L20))+6*LN(L20/('Read me'!$B$6+L20))),"") | O20: =IFERROR((1-N20)/M20,"") | Q20: =IF(P20="","",P20*M20+N20-1) | R20: =IF(Q20="","awaiting price",IF(Q20>='Read me'!$B$7,"BET",IF(Q20>=0,"thin","no bet")))
A21: 46298 | B21: England League One | C21: Burton Albion v Huddersfield | D21: Burton Albion | E21: Home | F21: Match under | G21: under 11 match corners | H21: 12 | I21: 12 | J21: 4/4 | K21: 8.6 | L21: 8.84 | M21: =IFERROR(POISSON(11-1,L21,TRUE),"") | N21: =IFERROR(POISSON(11,L21,FALSE),"") | O21: =IFERROR((1-N21)/M21,"") | Q21: =IF(P21="","",P21*M21+N21-1) | R21: =IF(Q21="","awaiting price",IF(Q21>='Read me'!$B$7,"BET",IF(Q21>=0,"thin","no bet")))
A22: 46299 | B22: Argentina Liga Profesional | C22: Huracan v Aldosivi | D22: Huracan | E22: Home | F22: Team under | G22: under 8 team corners | H22: 12 | I22: 12 | J22: 4/4 | K22: 3.4 | L22: 5.93 | M22: =IFERROR((EXP(GAMMALN(0+'Read me'!$B$6)-GAMMALN('Read me'!$B$6)-GAMMALN(0+1)+'Read me'!$B$6*LN('Read me'!$B$6/('Read me'!$B$6+L22))+0*LN(L22/('Read me'!$B$6+L22)))+EXP(GAMMALN(1+'Read me'!$B$6)-GAMMALN('Read me'!$B$6)-GAMMALN(1+1)+'Read me'!$B$6*LN('Read me'!$B$6/('Read me'!$B$6+L22))+1*LN(L22/('Read me'!$B$6+L22)))+EXP(GAMMALN(2+'Read me'!$B$6)-GAMMALN('Read me'!$B$6)-GAMMALN(2+1)+'Read me'!$B$6*LN('Read me'!$B$6/('Read me'!$B$6+L22))+2*LN(L22/('Read me'!$B$6+L22)))+EXP(GAMMALN(3+'Read me'!$B$6)-GAMMALN('Read me'!$B$6)-GAMMALN(3+1)+'Read me'!$B$6*LN('Read me'!$B$6/('Read me'!$B$6+L22))+3*LN(L22/('Read me'!$B$6+L22)))+EXP(GAMMALN(4+'Read me'!$B$6)-GAMMALN('Read me'!$B$6)-GAMMALN(4+1)+'Read me'!$B$6*LN('Read me'!$B$6/('Read me'!$B$6+L22))+4*LN(L22/('Read me'!$B$6+L22)))+EXP(GAMMALN(5+'Read me'!$B$6)-GAMMALN('Read me'!$B$6)-GAMMALN(5+1)+'Read me'!$B$6*LN('Read me'!$B$6/('Read me'!$B$6+L22))+5*LN(L22/('Read me'!$B$6+L22)))+EXP(GAMMALN(6+'Read me'!$B$6)-GAMMALN('Read me'!$B$6)-GAMMALN(6+1)+'Read me'!$B$6*LN('Read me'!$B$6/('Read me'!$B$6+L22))+6*LN(L22/('Read me'!$B$6+L22)))+EXP(GAMMALN(7+'Read me'!$B$6)-GAMMALN('Read me'!$B$6)-GAMMALN(7+1)+'Read me'!$B$6*LN('Read me'!$B$6/('Read me'!$B$6+L22))+7*LN(L22/('Read me'!$B$6+L22)))),"") | N22: =IFERROR(EXP(GAMMALN(8+'Read me'!$B$6)-GAMMALN('Read me'!$B$6)-GAMMALN(8+1)+'Read me'!$B$6*LN('Read me'!$B$6/('Read me'!$B$6+L22))+8*LN(L22/('Read me'!$B$6+L22))),"") | O22: =IFERROR((1-N22)/M22,"") | Q22: =IF(P22="","",P22*M22+N22-1) | R22: =IF(Q22="","awaiting price",IF(Q22>='Read me'!$B$7,"BET",IF(Q22>=0,"thin","no bet")))
A23: 46301 | B23: Argentina Liga Profesional | C23: Banfield v Rosario Central | D23: Banfield | E23: Home | F23: Match under | G23: under 12 match corners | H23: 12 | I23: 12 | J23: 4/4 | K23: 7.8 | L23: 8.21 | M23: =IFERROR(POISSON(12-1,L23,TRUE),"") | N23: =IFERROR(POISSON(12,L23,FALSE),"") | O23: =IFERROR((1-N23)/M23,"") | Q23: =IF(P23="","",P23*M23+N23-1) | R23: =IF(Q23="","awaiting price",IF(Q23>='Read me'!$B$7,"BET",IF(Q23>=0,"thin","no bet")))
A24: 46298 | B24: Netherlands Eerste Divisie | C24: Waalwijk v Emmen | D24: Waalwijk | E24: Home | F24: Team under | G24: under 7 team corners | H24: 11 | I24: 11 | J24: 4/4 | K24: 4.6 | L24: 4.27 | M24: =IFERROR((EXP(GAMMALN(0+'Read me'!$B$6)-GAMMALN('Read me'!$B$6)-GAMMALN(0+1)+'Read me'!$B$6*LN('Read me'!$B$6/('Read me'!$B$6+L24))+0*LN(L24/('Read me'!$B$6+L24)))+EXP(GAMMALN(1+'Read me'!$B$6)-GAMMALN('Read me'!$B$6)-GAMMALN(1+1)+'Read me'!$B$6*LN('Read me'!$B$6/('Read me'!$B$6+L24))+1*LN(L24/('Read me'!$B$6+L24)))+EXP(GAMMALN(2+'Read me'!$B$6)-GAMMALN('Read me'!$B$6)-GAMMALN(2+1)+'Read me'!$B$6*LN('Read me'!$B$6/('Read me'!$B$6+L24))+2*LN(L24/('Read me'!$B$6+L24)))+EXP(GAMMALN(3+'Read me'!$B$6)-GAMMALN('Read me'!$B$6)-GAMMALN(3+1)+'Read me'!$B$6*LN('Read me'!$B$6/('Read me'!$B$6+L24))+3*LN(L24/('Read me'!$B$6+L24)))+EXP(GAMMALN(4+'Read me'!$B$6)-GAMMALN('Read me'!$B$6)-GAMMALN(4+1)+'Read me'!$B$6*LN('Read me'!$B$6/('Read me'!$B$6+L24))+4*LN(L24/('Read me'!$B$6+L24)))+EXP(GAMMALN(5+'Read me'!$B$6)-GAMMALN('Read me'!$B$6)-GAMMALN(5+1)+'Read me'!$B$6*LN('Read me'!$B$6/('Read me'!$B$6+L24))+5*LN(L24/('Read me'!$B$6+L24)))+EXP(GAMMALN(6+'Read me'!$B$6)-GAMMALN('Read me'!$B$6)-GAMMALN(6+1)+'Read me'!$B$6*LN('Read me'!$B$6/('Read me'!$B$6+L24))+6*LN(L24/('Read me'!$B$6+L24)))),"") | N24: =IFERROR(EXP(GAMMALN(7+'Read me'!$B$6)-GAMMALN('Read me'!$B$6)-GAMMALN(7+1)+'Read me'!$B$6*LN('Read me'!$B$6/('Read me'!$B$6+L24))+7*LN(L24/('Read me'!$B$6+L24))),"") | O24: =IFERROR((1-N24)/M24,"") | Q24: =IF(P24="","",P24*M24+N24-1) | R24: =IF(Q24="","awaiting price",IF(Q24>='Read me'!$B$7,"BET",IF(Q24>=0,"thin","no bet")))
A25: 46298 | B25: England League Two | C25: Chesterfield v Tranmere | D25: Tranmere | E25: Away | F25: Match under | G25: under 12 match corners | H25: 11 | I25: 11 | J25: 4/4 | K25: 9.4 | L25: 9.83 | M25: =IFERROR(POISSON(12-1,L25,TRUE),"") | N25: =IFERROR(POISSON(12,L25,FALSE),"") | O25: =IFERROR((1-N25)/M25,"") | Q25: =IF(P25="","",P25*M25+N25-1) | R25: =IF(Q25="","awaiting price",IF(Q25>='Read me'!$B$7,"BET",IF(Q25>=0,"thin","no bet")))
A26: 46302 | B26: Brazil Série A | C26: Internacional v Corinthians | D26: Internacional | E26: Home | F26: Team under | G26: under 7 team corners | H26: 11 | I26: 11 | J26: 4/4 | K26: 4 | L26: 5.72 | M26: =IFERROR((EXP(GAMMALN(0+'Read me'!$B$6)-GAMMALN('Read me'!$B$6)-GAMMALN(0+1)+'Read me'!$B$6*LN('Read me'!$B$6/('Read me'!$B$6+L26))+0*LN(L26/('Read me'!$B$6+L26)))+EXP(GAMMALN(1+'Read me'!$B$6)-GAMMALN('Read me'!$B$6)-GAMMALN(1+1)+'Read me'!$B$6*LN('Read me'!$B$6/('Read me'!$B$6+L26))+1*LN(L26/('Read me'!$B$6+L26)))+EXP(GAMMALN(2+'Read me'!$B$6)-GAMMALN('Read me'!$B$6)-GAMMALN(2+1)+'Read me'!$B$6*LN('Read me'!$B$6/('Read me'!$B$6+L26))+2*LN(L26/('Read me'!$B$6+L26)))+EXP(GAMMALN(3+'Read me'!$B$6)-GAMMALN('Read me'!$B$6)-GAMMALN(3+1)+'Read me'!$B$6*LN('Read me'!$B$6/('Read me'!$B$6+L26))+3*LN(L26/('Read me'!$B$6+L26)))+EXP(GAMMALN(4+'Read me'!$B$6)-GAMMALN('Read me'!$B$6)-GAMMALN(4+1)+'Read me'!$B$6*LN('Read me'!$B$6/('Read me'!$B$6+L26))+4*LN(L26/('Read me'!$B$6+L26)))+EXP(GAMMALN(5+'Read me'!$B$6)-GAMMALN('Read me'!$B$6)-GAMMALN(5+1)+'Read me'!$B$6*LN('Read me'!$B$6/('Read me'!$B$6+L26))+5*LN(L26/('Read me'!$B$6+L26)))+EXP(GAMMALN(6+'Read me'!$B$6)-GAMMALN('Read me'!$B$6)-GAMMALN(6+1)+'Read me'!$B$6*LN('Read me'!$B$6/('Read me'!$B$6+L26))+6*LN(L26/('Read me'!$B$6+L26)))),"") | N26: =IFERROR(EXP(GAMMALN(7+'Read me'!$B$6)-GAMMALN('Read me'!$B$6)-GAMMALN(7+1)+'Read me'!$B$6*LN('Read me'!$B$6/('Read me'!$B$6+L26))+7*LN(L26/('Read me'!$B$6+L26))),"") | O26: =IFERROR((1-N26)/M26,"") | Q26: =IF(P26="","",P26*M26+N26-1) | R26: =IF(Q26="","awaiting price",IF(Q26>='Read me'!$B$7,"BET",IF(Q26>=0,"thin","no bet")))
A27: 46297 | B27: Brazil Série B | C27: Juventude v Operario-PR | D27: Juventude | E27: Home | F27: Team under | G27: under 7 team corners | H27: 10 | I27: 10 | J27: 4/4 | K27: 3.6 | L27: 5.83 | M27: =IFERROR((EXP(GAMMALN(0+'Read me'!$B$6)-GAMMALN('Read me'!$B$6)-GAMMALN(0+1)+'Read me'!$B$6*LN('Read me'!$B$6/('Read me'!$B$6+L27))+0*LN(L27/('Read me'!$B$6+L27)))+EXP(GAMMALN(1+'Read me'!$B$6)-GAMMALN('Read me'!$B$6)-GAMMALN(1+1)+'Read me'!$B$6*LN('Read me'!$B$6/('Read me'!$B$6+L27))+1*LN(L27/('Read me'!$B$6+L27)))+EXP(GAMMALN(2+'Read me'!$B$6)-GAMMALN('Read me'!$B$6)-GAMMALN(2+1)+'Read me'!$B$6*LN('Read me'!$B$6/('Read me'!$B$6+L27))+2*LN(L27/('Read me'!$B$6+L27)))+EXP(GAMMALN(3+'Read me'!$B$6)-GAMMALN('Read me'!$B$6)-GAMMALN(3+1)+'Read me'!$B$6*LN('Read me'!$B$6/('Read me'!$B$6+L27))+3*LN(L27/('Read me'!$B$6+L27)))+EXP(GAMMALN(4+'Read me'!$B$6)-GAMMALN('Read me'!$B$6)-GAMMALN(4+1)+'Read me'!$B$6*LN('Read me'!$B$6/('Read me'!$B$6+L27))+4*LN(L27/('Read me'!$B$6+L27)))+EXP(GAMMALN(5+'Read me'!$B$6)-GAMMALN('Read me'!$B$6)-GAMMALN(5+1)+'Read me'!$B$6*LN('Read me'!$B$6/('Read me'!$B$6+L27))+5*LN(L27/('Read me'!$B$6+L27)))+EXP(GAMMALN(6+'Read me'!$B$6)-GAMMALN('Read me'!$B$6)-GAMMALN(6+1)+'Read me'!$B$6*LN('Read me'!$B$6/('Read me'!$B$6+L27))+6*LN(L27/('Read me'!$B$6+L27)))),"") | N27: =IFERROR(EXP(GAMMALN(7+'Read me'!$B$6)-GAMMALN('Read me'!$B$6)-GAMMALN(7+1)+'Read me'!$B$6*LN('Read me'!$B$6/('Read me'!$B$6+L27))+7*LN(L27/('Read me'!$B$6+L27))),"") | O27: =IFERROR((1-N27)/M27,"") | Q27: =IF(P27="","",P27*M27+N27-1) | R27: =IF(Q27="","awaiting price",IF(Q27>='Read me'!$B$7,"BET",IF(Q27>=0,"thin","no bet")))
A28: 46297 | B28: Brazil Série B | C28: São Bernardo v CRB | D28: CRB | E28: Away | F28: Team under | G28: under 7 team corners | H28: 10 | I28: 10 | J28: 3/3 | K28: 6.2 | L28: 5.83 | M28: =IFERROR((EXP(GAMMALN(0+'Read me'!$B$6)-GAMMALN('Read me'!$B$6)-GAMMALN(0+1)+'Read me'!$B$6*LN('Read me'!$B$6/('Read me'!$B$6+L28))+0*LN(L28/('Read me'!$B$6+L28)))+EXP(GAMMALN(1+'Read me'!$B$6)-GAMMALN('Read me'!$B$6)-GAMMALN(1+1)+'Read me'!$B$6*LN('Read me'!$B$6/('Read me'!$B$6+L28))+1*LN(L28/('Read me'!$B$6+L28)))+EXP(GAMMALN(2+'Read me'!$B$6)-GAMMALN('Read me'!$B$6)-GAMMALN(2+1)+'Read me'!$B$6*LN('Read me'!$B$6/('Read me'!$B$6+L28))+2*LN(L28/('Read me'!$B$6+L28)))+EXP(GAMMALN(3+'Read me'!$B$6)-GAMMALN('Read me'!$B$6)-GAMMALN(3+1)+'Read me'!$B$6*LN('Read me'!$B$6/('Read me'!$B$6+L28))+3*LN(L28/('Read me'!$B$6+L28)))+EXP(GAMMALN(4+'Read me'!$B$6)-GAMMALN('Read me'!$B$6)-GAMMALN(4+1)+'Read me'!$B$6*LN('Read me'!$B$6/('Read me'!$B$6+L28))+4*LN(L28/('Read me'!$B$6+L28)))+EXP(GAMMALN(5+'Read me'!$B$6)-GAMMALN('Read me'!$B$6)-GAMMALN(5+1)+'Read me'!$B$6*LN('Read me'!$B$6/('Read me'!$B$6+L28))+5*LN(L28/('Read me'!$B$6+L28)))+EXP(GAMMALN(6+'Read me'!$B$6)-GAMMALN('Read me'!$B$6)-GAMMALN(6+1)+'Read me'!$B$6*LN('Read me'!$B$6/('Read me'!$B$6+L28))+6*LN(L28/('Read me'!$B$6+L28)))),"") | N28: =IFERROR(EXP(GAMMALN(7+'Read me'!$B$6)-GAMMALN('Read me'!$B$6)-GAMMALN(7+1)+'Read me'!$B$6*LN('Read me'!$B$6/('Read me'!$B$6+L28))+7*LN(L28/('Read me'!$B$6+L28))),"") | O28: =IFERROR((1-N28)/M28,"") | Q28: =IF(P28="","",P28*M28+N28-1) | R28: =IF(Q28="","awaiting price",IF(Q28>='Read me'!$B$7,"BET",IF(Q28>=0,"thin","no bet")))
A29: 46298 | B29: England League Two | C29: Walsall v Crawley Town | D29: Walsall | E29: Home | F29: Team over | G29: 4+ team corners | H29: 10 | I29: 10 | J29: 5/5 | K29: 6.2 | L29: 5.5 | M29: =IFERROR(1-(EXP(GAMMALN(0+'Read me'!$B$6)-GAMMALN('Read me'!$B$6)-GAMMALN(0+1)+'Read me'!$B$6*LN('Read me'!$B$6/('Read me'!$B$6+L29))+0*LN(L29/('Read me'!$B$6+L29)))+EXP(GAMMALN(1+'Read me'!$B$6)-GAMMALN('Read me'!$B$6)-GAMMALN(1+1)+'Read me'!$B$6*LN('Read me'!$B$6/('Read me'!$B$6+L29))+1*LN(L29/('Read me'!$B$6+L29)))+EXP(GAMMALN(2+'Read me'!$B$6)-GAMMALN('Read me'!$B$6)-GAMMALN(2+1)+'Read me'!$B$6*LN('Read me'!$B$6/('Read me'!$B$6+L29))+2*LN(L29/('Read me'!$B$6+L29)))+EXP(GAMMALN(3+'Read me'!$B$6)-GAMMALN('Read me'!$B$6)-GAMMALN(3+1)+'Read me'!$B$6*LN('Read me'!$B$6/('Read me'!$B$6+L29))+3*LN(L29/('Read me'!$B$6+L29)))),"") | N29: 0 | O29: =IFERROR(1/M29,"") | Q29: =IF(P29="","",P29*M29-1) | R29: =IF(Q29="","awaiting price",IF(Q29>='Read me'!$B$7,"BET",IF(Q29>=0,"thin","no bet")))
A30: 46298 | B30: England League One | C30: Burton Albion v Huddersfield | D30: Burton Albion | E30: Home | F30: Team under | G30: under 5 team corners | H30: 10 | I30: 10 | J30: 4/4 | K30: 3.8 | L30: 4.52 | M30: =IFERROR((EXP(GAMMALN(0+'Read me'!$B$6)-GAMMALN('Read me'!$B$6)-GAMMALN(0+1)+'Read me'!$B$6*LN('Read me'!$B$6/('Read me'!$B$6+L30))+0*LN(L30/('Read me'!$B$6+L30)))+EXP(GAMMALN(1+'Read me'!$B$6)-GAMMALN('Read me'!$B$6)-GAMMALN(1+1)+'Read me'!$B$6*LN('Read me'!$B$6/('Read me'!$B$6+L30))+1*LN(L30/('Read me'!$B$6+L30)))+EXP(GAMMALN(2+'Read me'!$B$6)-GAMMALN('Read me'!$B$6)-GAMMALN(2+1)+'Read me'!$B$6*LN('Read me'!$B$6/('Read me'!$B$6+L30))+2*LN(L30/('Read me'!$B$6+L30)))+EXP(GAMMALN(3+'Read me'!$B$6)-GAMMALN('Read me'!$B$6)-GAMMALN(3+1)+'Read me'!$B$6*LN('Read me'!$B$6/('Read me'!$B$6+L30))+3*LN(L30/('Read me'!$B$6+L30)))+EXP(GAMMALN(4+'Read me'!$B$6)-GAMMALN('Read me'!$B$6)-GAMMALN(4+1)+'Read me'!$B$6*LN('Read me'!$B$6/('Read me'!$B$6+L30))+4*LN(L30/('Read me'!$B$6+L30)))),"") | N30: =IFERROR(EXP(GAMMALN(5+'Read me'!$B$6)-GAMMALN('Read me'!$B$6)-GAMMALN(5+1)+'Read me'!$B$6*LN('Read me'!$B$6/('Read me'!$B$6+L30))+5*LN(L30/('Read me'!$B$6+L30))),"") | O30: =IFERROR((1-N30)/M30,"") | Q30: =IF(P30="","",P30*M30+N30-1) | R30: =IF(Q30="","awaiting price",IF(Q30>='Read me'!$B$7,"BET",IF(Q30>=0,"thin","no bet")))
A31: 46298 | B31: Argentina Liga Profesional | C31: Independ. Rivadavia v Gimnasia L.P. | D31: Gimnasia L.P. | E31: Away | F31: Team under | G31: under 5 team corners | H31: 10 | I31: 10 | J31: 3/3 | K31: 3.8 | L31: 3.79 | M31: =IFERROR((EXP(GAMMALN(0+'Read me'!$B$6)-GAMMALN('Read me'!$B$6)-GAMMALN(0+1)+'Read me'!$B$6*LN('Read me'!$B$6/('Read me'!$B$6+L31))+0*LN(L31/('Read me'!$B$6+L31)))+EXP(GAMMALN(1+'Read me'!$B$6)-GAMMALN('Read me'!$B$6)-GAMMALN(1+1)+'Read me'!$B$6*LN('Read me'!$B$6/('Read me'!$B$6+L31))+1*LN(L31/('Read me'!$B$6+L31)))+EXP(GAMMALN(2+'Read me'!$B$6)-GAMMALN('Read me'!$B$6)-GAMMALN(2+1)+'Read me'!$B$6*LN('Read me'!$B$6/('Read me'!$B$6+L31))+2*LN(L31/('Read me'!$B$6+L31)))+EXP(GAMMALN(3+'Read me'!$B$6)-GAMMALN('Read me'!$B$6)-GAMMALN(3+1)+'Read me'!$B$6*LN('Read me'!$B$6/('Read me'!$B$6+L31))+3*LN(L31/('Read me'!$B$6+L31)))+EXP(GAMMALN(4+'Read me'!$B$6)-GAMMALN('Read me'!$B$6)-GAMMALN(4+1)+'Read me'!$B$6*LN('Read me'!$B$6/('Read me'!$B$6+L31))+4*LN(L31/('Read me'!$B$6+L31)))),"") | N31: =IFERROR(EXP(GAMMALN(5+'Read me'!$B$6)-GAMMALN('Read me'!$B$6)-GAMMALN(5+1)+'Read me'!$B$6*LN('Read me'!$B$6/('Read me'!$B$6+L31))+5*LN(L31/('Read me'!$B$6+L31))),"") | O31: =IFERROR((1-N31)/M31,"") | Q31: =IF(P31="","",P31*M31+N31-1) | R31: =IF(Q31="","awaiting price",IF(Q31>='Read me'!$B$7,"BET",IF(Q31>=0,"thin","no bet")))
A32: 46298 | B32: England League Two | C32: Chesterfield v Tranmere | D32: Tranmere | E32: Away | F32: Team under | G32: under 6 team corners | H32: 10 | I32: 10 | J32: 4/4 | K32: 3.4 | L32: 3.88 | M32: =IFERROR((EXP(GAMMALN(0+'Read me'!$B$6)-GAMMALN('Read me'!$B$6)-GAMMALN(0+1)+'Read me'!$B$6*LN('Read me'!$B$6/('Read me'!$B$6+L32))+0*LN(L32/('Read me'!$B$6+L32)))+EXP(GAMMALN(1+'Read me'!$B$6)-GAMMALN('Read me'!$B$6)-GAMMALN(1+1)+'Read me'!$B$6*LN('Read me'!$B$6/('Read me'!$B$6+L32))+1*LN(L32/('Read me'!$B$6+L32)))+EXP(GAMMALN(2+'Read me'!$B$6)-GAMMALN('Read me'!$B$6)-GAMMALN(2+1)+'Read me'!$B$6*LN('Read me'!$B$6/('Read me'!$B$6+L32))+2*LN(L32/('Read me'!$B$6+L32)))+EXP(GAMMALN(3+'Read me'!$B$6)-GAMMALN('Read me'!$B$6)-GAMMALN(3+1)+'Read me'!$B$6*LN('Read me'!$B$6/('Read me'!$B$6+L32))+3*LN(L32/('Read me'!$B$6+L32)))+EXP(GAMMALN(4+'Read me'!$B$6)-GAMMALN('Read me'!$B$6)-GAMMALN(4+1)+'Read me'!$B$6*LN('Read me'!$B$6/('Read me'!$B$6+L32))+4*LN(L32/('Read me'!$B$6+L32)))+EXP(GAMMALN(5+'Read me'!$B$6)-GAMMALN('Read me'!$B$6)-GAMMALN(5+1)+'Read me'!$B$6*LN('Read me'!$B$6/('Read me'!$B$6+L32))+5*LN(L32/('Read me'!$B$6+L32)))),"") | N32: =IFERROR(EXP(GAMMALN(6+'Read me'!$B$6)-GAMMALN('Read me'!$B$6)-GAMMALN(6+1)+'Read me'!$B$6*LN('Read me'!$B$6/('Read me'!$B$6+L32))+6*LN(L32/('Read me'!$B$6+L32))),"") | O32: =IFERROR((1-N32)/M32,"") | Q32: =IF(P32="","",P32*M32+N32-1) | R32: =IF(Q32="","awaiting price",IF(Q32>='Read me'!$B$7,"BET",IF(Q32>=0,"thin","no bet")))
A33: 46303 | B33: Brazil Série A | C33: Atletico Paranaense v Atletico-MG | D33: Atletico Paranaense | E33: Home | F33: Team under | G33: under 8 team corners | H33: 10 | I33: 10 | J33: 4/4 | K33: 4.2 | L33: 6.02 | M33: =IFERROR((EXP(GAMMALN(0+'Read me'!$B$6)-GAMMALN('Read me'!$B$6)-GAMMALN(0+1)+'Read me'!$B$6*LN('Read me'!$B$6/('Read me'!$B$6+L33))+0*LN(L33/('Read me'!$B$6+L33)))+EXP(GAMMALN(1+'Read me'!$B$6)-GAMMALN('Read me'!$B$6)-GAMMALN(1+1)+'Read me'!$B$6*LN('Read me'!$B$6/('Read me'!$B$6+L33))+1*LN(L33/('Read me'!$B$6+L33)))+EXP(GAMMALN(2+'Read me'!$B$6)-GAMMALN('Read me'!$B$6)-GAMMALN(2+1)+'Read me'!$B$6*LN('Read me'!$B$6/('Read me'!$B$6+L33))+2*LN(L33/('Read me'!$B$6+L33)))+EXP(GAMMALN(3+'Read me'!$B$6)-GAMMALN('Read me'!$B$6)-GAMMALN(3+1)+'Read me'!$B$6*LN('Read me'!$B$6/('Read me'!$B$6+L33))+3*LN(L33/('Read me'!$B$6+L33)))+EXP(GAMMALN(4+'Read me'!$B$6)-GAMMALN('Read me'!$B$6)-GAMMALN(4+1)+'Read me'!$B$6*LN('Read me'!$B$6/('Read me'!$B$6+L33))+4*LN(L33/('Read me'!$B$6+L33)))+EXP(GAMMALN(5+'Read me'!$B$6)-GAMMALN('Read me'!$B$6)-GAMMALN(5+1)+'Read me'!$B$6*LN('Read me'!$B$6/('Read me'!$B$6+L33))+5*LN(L33/('Read me'!$B$6+L33)))+EXP(GAMMALN(6+'Read me'!$B$6)-GAMMALN('Read me'!$B$6)-GAMMALN(6+1)+'Read me'!$B$6*LN('Read me'!$B$6/('Read me'!$B$6+L33))+6*LN(L33/('Read me'!$B$6+L33)))+EXP(GAMMALN(7+'Read me'!$B$6)-GAMMALN('Read me'!$B$6)-GAMMALN(7+1)+'Read me'!$B$6*LN('Read me'!$B$6/('Read me'!$B$6+L33))+7*LN(L33/('Read me'!$B$6+L33)))),"") | N33: =IFERROR(EXP(GAMMALN(8+'Read me'!$B$6)-GAMMALN('Read me'!$B$6)-GAMMALN(8+1)+'Read me'!$B$6*LN('Read me'!$B$6/('Read me'!$B$6+L33))+8*LN(L33/('Read me'!$B$6+L33))),"") | O33: =IFERROR((1-N33)/M33,"") | Q33: =IF(P33="","",P33*M33+N33-1) | R33: =IF(Q33="","awaiting price",IF(Q33>='Read me'!$B$7,"BET",IF(Q33>=0,"thin","no bet")))
A34: 46297 | B34: Brazil Série B | C34: Novorizontino v Goias | D34: Goias | E34: Away | F34: Team under | G34: under 8 team corners | H34: 9 | I34: 9 | J34: 4/4 | K34: 6.6 | L34: 3.95 | M34: =IFERROR((EXP(GAMMALN(0+'Read me'!$B$6)-GAMMALN('Read me'!$B$6)-GAMMALN(0+1)+'Read me'!$B$6*LN('Read me'!$B$6/('Read me'!$B$6+L34))+0*LN(L34/('Read me'!$B$6+L34)))+EXP(GAMMALN(1+'Read me'!$B$6)-GAMMALN('Read me'!$B$6)-GAMMALN(1+1)+'Read me'!$B$6*LN('Read me'!$B$6/('Read me'!$B$6+L34))+1*LN(L34/('Read me'!$B$6+L34)))+EXP(GAMMALN(2+'Read me'!$B$6)-GAMMALN('Read me'!$B$6)-GAMMALN(2+1)+'Read me'!$B$6*LN('Read me'!$B$6/('Read me'!$B$6+L34))+2*LN(L34/('Read me'!$B$6+L34)))+EXP(GAMMALN(3+'Read me'!$B$6)-GAMMALN('Read me'!$B$6)-GAMMALN(3+1)+'Read me'!$B$6*LN('Read me'!$B$6/('Read me'!$B$6+L34))+3*LN(L34/('Read me'!$B$6+L34)))+EXP(GAMMALN(4+'Read me'!$B$6)-GAMMALN('Read me'!$B$6)-GAMMALN(4+1)+'Read me'!$B$6*LN('Read me'!$B$6/('Read me'!$B$6+L34))+4*LN(L34/('Read me'!$B$6+L34)))+EXP(GAMMALN(5+'Read me'!$B$6)-GAMMALN('Read me'!$B$6)-GAMMALN(5+1)+'Read me'!$B$6*LN('Read me'!$B$6/('Read me'!$B$6+L34))+5*LN(L34/('Read me'!$B$6+L34)))+EXP(GAMMALN(6+'Read me'!$B$6)-GAMMALN('Read me'!$B$6)-GAMMALN(6+1)+'Read me'!$B$6*LN('Read me'!$B$6/('Read me'!$B$6+L34))+6*LN(L34/('Read me'!$B$6+L34)))+EXP(GAMMALN(7+'Read me'!$B$6)-GAMMALN('Read me'!$B$6)-GAMMALN(7+1)+'Read me'!$B$6*LN('Read me'!$B$6/('Read me'!$B$6+L34))+7*LN(L34/('Read me'!$B$6+L34)))),"") | N34: =IFERROR(EXP(GAMMALN(8+'Read me'!$B$6)-GAMMALN('Read me'!$B$6)-GAMMALN(8+1)+'Read me'!$B$6*LN('Read me'!$B$6/('Read me'!$B$6+L34))+8*LN(L34/('Read me'!$B$6+L34))),"") | O34: =IFERROR((1-N34)/M34,"") | Q34: =IF(P34="","",P34*M34+N34-1) | R34: =IF(Q34="","awaiting price",IF(Q34>='Read me'!$B$7,"BET",IF(Q34>=0,"thin","no bet")))
A35: 46298 | B35: England League One | C35: Leyton Orient v Plymouth | D35: Leyton Orient | E35: Home | F35: Team under | G35: under 6 team corners | H35: 9 | I35: 9 | J35: 4/4 | K35: 3.8 | L35: 4.95 | M35: =IFERROR((EXP(GAMMALN(0+'Read me'!$B$6)-GAMMALN('Read me'!$B$6)-GAMMALN(0+1)+'Read me'!$B$6*LN('Read me'!$B$6/('Read me'!$B$6+L35))+0*LN(L35/('Read me'!$B$6+L35)))+EXP(GAMMALN(1+'Read me'!$B$6)-GAMMALN('Read me'!$B$6)-GAMMALN(1+1)+'Read me'!$B$6*LN('Read me'!$B$6/('Read me'!$B$6+L35))+1*LN(L35/('Read me'!$B$6+L35)))+EXP(GAMMALN(2+'Read me'!$B$6)-GAMMALN('Read me'!$B$6)-GAMMALN(2+1)+'Read me'!$B$6*LN('Read me'!$B$6/('Read me'!$B$6+L35))+2*LN(L35/('Read me'!$B$6+L35)))+EXP(GAMMALN(3+'Read me'!$B$6)-GAMMALN('Read me'!$B$6)-GAMMALN(3+1)+'Read me'!$B$6*LN('Read me'!$B$6/('Read me'!$B$6+L35))+3*LN(L35/('Read me'!$B$6+L35)))+EXP(GAMMALN(4+'Read me'!$B$6)-GAMMALN('Read me'!$B$6)-GAMMALN(4+1)+'Read me'!$B$6*LN('Read me'!$B$6/('Read me'!$B$6+L35))+4*LN(L35/('Read me'!$B$6+L35)))+EXP(GAMMALN(5+'Read me'!$B$6)-GAMMALN('Read me'!$B$6)-GAMMALN(5+1)+'Read me'!$B$6*LN('Read me'!$B$6/('Read me'!$B$6+L35))+5*LN(L35/('Read me'!$B$6+L35)))),"") | N35: =IFERROR(EXP(GAMMALN(6+'Read me'!$B$6)-GAMMALN('Read me'!$B$6)-GAMMALN(6+1)+'Read me'!$B$6*LN('Read me'!$B$6/('Read me'!$B$6+L35))+6*LN(L35/('Read me'!$B$6+L35))),"") | O35: =IFERROR((1-N35)/M35,"") | Q35: =IF(P35="","",P35*M35+N35-1) | R35: =IF(Q35="","awaiting price",IF(Q35>='Read me'!$B$7,"BET",IF(Q35>=0,"thin","no bet")))
A36: 46299 | B36: Netherlands Eerste Divisie | C36: VVV Venlo v Roda | D36: VVV Venlo | E36: Home | F36: Team under | G36: under 8 team corners | H36: 9 | I36: 9 | J36: 4/4 | K36: 5.8 | L36: 5.48 | M36: =IFERROR((EXP(GAMMALN(0+'Read me'!$B$6)-GAMMALN('Read me'!$B$6)-GAMMALN(0+1)+'Read me'!$B$6*LN('Read me'!$B$6/('Read me'!$B$6+L36))+0*LN(L36/('Read me'!$B$6+L36)))+EXP(GAMMALN(1+'Read me'!$B$6)-GAMMALN('Read me'!$B$6)-GAMMALN(1+1)+'Read me'!$B$6*LN('Read me'!$B$6/('Read me'!$B$6+L36))+1*LN(L36/('Read me'!$B$6+L36)))+EXP(GAMMALN(2+'Read me'!$B$6)-GAMMALN('Read me'!$B$6)-GAMMALN(2+1)+'Read me'!$B$6*LN('Read me'!$B$6/('Read me'!$B$6+L36))+2*LN(L36/('Read me'!$B$6+L36)))+EXP(GAMMALN(3+'Read me'!$B$6)-GAMMALN('Read me'!$B$6)-GAMMALN(3+1)+'Read me'!$B$6*LN('Read me'!$B$6/('Read me'!$B$6+L36))+3*LN(L36/('Read me'!$B$6+L36)))+EXP(GAMMALN(4+'Read me'!$B$6)-GAMMALN('Read me'!$B$6)-GAMMALN(4+1)+'Read me'!$B$6*LN('Read me'!$B$6/('Read me'!$B$6+L36))+4*LN(L36/('Read me'!$B$6+L36)))+EXP(GAMMALN(5+'Read me'!$B$6)-GAMMALN('Read me'!$B$6)-GAMMALN(5+1)+'Read me'!$B$6*LN('Read me'!$B$6/('Read me'!$B$6+L36))+5*LN(L36/('Read me'!$B$6+L36)))+EXP(GAMMALN(6+'Read me'!$B$6)-GAMMALN('Read me'!$B$6)-GAMMALN(6+1)+'Read me'!$B$6*LN('Read me'!$B$6/('Read me'!$B$6+L36))+6*LN(L36/('Read me'!$B$6+L36)))+EXP(GAMMALN(7+'Read me'!$B$6)-GAMMALN('Read me'!$B$6)-GAMMALN(7+1)+'Read me'!$B$6*LN('Read me'!$B$6/('Read me'!$B$6+L36))+7*LN(L36/('Read me'!$B$6+L36)))),"") | N36: =IFERROR(EXP(GAMMALN(8+'Read me'!$B$6)-GAMMALN('Read me'!$B$6)-GAMMALN(8+1)+'Read me'!$B$6*LN('Read me'!$B$6/('Read me'!$B$6+L36))+8*LN(L36/('Read me'!$B$6+L36))),"") | O36: =IFERROR((1-N36)/M36,"") | Q36: =IF(P36="","",P36*M36+N36-1) | R36: =IF(Q36="","awaiting price",IF(Q36>='Read me'!$B$7,"BET",IF(Q36>=0,"thin","no bet")))
A37: 46299 | B37: Netherlands Eerste Divisie | C37: VVV Venlo v Roda | D37: VVV Venlo | E37: Home | F37: Match under | G37: under 12 match corners | H37: 9 | I37: 9 | J37: 4/4 | K37: 10.4 | L37: 10.11 | M37: =IFERROR(POISSON(12-1,L37,TRUE),"") | N37: =IFERROR(POISSON(12,L37,FALSE),"") | O37: =IFERROR((1-N37)/M37,"") | Q37: =IF(P37="","",P37*M37+N37-1) | R37: =IF(Q37="","awaiting price",IF(Q37>='Read me'!$B$7,"BET",IF(Q37>=0,"thin","no bet")))
A38: 46297 | B38: Netherlands Eerste Divisie | C38: Helmond Sport v Heracles | D38: Heracles | E38: Away | F38: Team over | G38: 5+ team corners | H38: 8 | I38: 8 | J38: 5/5 | K38: 7.8 | L38: 6.02 | M38: =IFERROR(1-(EXP(GAMMALN(0+'Read me'!$B$6)-GAMMALN('Read me'!$B$6)-GAMMALN(0+1)+'Read me'!$B$6*LN('Read me'!$B$6/('Read me'!$B$6+L38))+0*LN(L38/('Read me'!$B$6+L38)))+EXP(GAMMALN(1+'Read me'!$B$6)-GAMMALN('Read me'!$B$6)-GAMMALN(1+1)+'Read me'!$B$6*LN('Read me'!$B$6/('Read me'!$B$6+L38))+1*LN(L38/('Read me'!$B$6+L38)))+EXP(GAMMALN(2+'Read me'!$B$6)-GAMMALN('Read me'!$B$6)-GAMMALN(2+1)+'Read me'!$B$6*LN('Read me'!$B$6/('Read me'!$B$6+L38))+2*LN(L38/('Read me'!$B$6+L38)))+EXP(GAMMALN(3+'Read me'!$B$6)-GAMMALN('Read me'!$B$6)-GAMMALN(3+1)+'Read me'!$B$6*LN('Read me'!$B$6/('Read me'!$B$6+L38))+3*LN(L38/('Read me'!$B$6+L38)))+EXP(GAMMALN(4+'Read me'!$B$6)-GAMMALN('Read me'!$B$6)-GAMMALN(4+1)+'Read me'!$B$6*LN('Read me'!$B$6/('Read me'!$B$6+L38))+4*LN(L38/('Read me'!$B$6+L38)))),"") | N38: 0 | O38: =IFERROR(1/M38,"") | Q38: =IF(P38="","",P38*M38-1) | R38: =IF(Q38="","awaiting price",IF(Q38>='Read me'!$B$7,"BET",IF(Q38>=0,"thin","no bet")))
A39: 46297 | B39: USA MLS | C39: Seattle Sounders v Sporting Kansas City | D39: Seattle Sounders | E39: Home | F39: Team over | G39: 3+ team corners | H39: 8 | I39: 8 | J39: 5/5 | K39: 6 | L39: 5.34 | M39: =IFERROR(1-(EXP(GAMMALN(0+'Read me'!$B$6)-GAMMALN('Read me'!$B$6)-GAMMALN(0+1)+'Read me'!$B$6*LN('Read me'!$B$6/('Read me'!$B$6+L39))+0*LN(L39/('Read me'!$B$6+L39)))+EXP(GAMMALN(1+'Read me'!$B$6)-GAMMALN('Read me'!$B$6)-GAMMALN(1+1)+'Read me'!$B$6*LN('Read me'!$B$6/('Read me'!$B$6+L39))+1*LN(L39/('Read me'!$B$6+L39)))+EXP(GAMMALN(2+'Read me'!$B$6)-GAMMALN('Read me'!$B$6)-GAMMALN(2+1)+'Read me'!$B$6*LN('Read me'!$B$6/('Read me'!$B$6+L39))+2*LN(L39/('Read me'!$B$6+L39)))),"") | N39: 0 | O39: =IFERROR(1/M39,"") | Q39: =IF(P39="","",P39*M39-1) | R39: =IF(Q39="","awaiting price",IF(Q39>='Read me'!$B$7,"BET",IF(Q39>=0,"thin","no bet")))
A40: 46298 | B40: Netherlands Eerste Divisie | C40: Den Bosch v Dordrecht | D40: Den Bosch | E40: Home | F40: Team over | G40: 5+ team corners | H40: 8 | I40: 8 | J40: 5/5 | K40: 9.6 | L40: 5.87 | M40: =IFERROR(1-(EXP(GAMMALN(0+'Read me'!$B$6)-GAMMALN('Read me'!$B$6)-GAMMALN(0+1)+'Read me'!$B$6*LN('Read me'!$B$6/('Read me'!$B$6+L40))+0*LN(L40/('Read me'!$B$6+L40)))+EXP(GAMMALN(1+'Read me'!$B$6)-GAMMALN('Read me'!$B$6)-GAMMALN(1+1)+'Read me'!$B$6*LN('Read me'!$B$6/('Read me'!$B$6+L40))+1*LN(L40/('Read me'!$B$6+L40)))+EXP(GAMMALN(2+'Read me'!$B$6)-GAMMALN('Read me'!$B$6)-GAMMALN(2+1)+'Read me'!$B$6*LN('Read me'!$B$6/('Read me'!$B$6+L40))+2*LN(L40/('Read me'!$B$6+L40)))+EXP(GAMMALN(3+'Read me'!$B$6)-GAMMALN('Read me'!$B$6)-GAMMALN(3+1)+'Read me'!$B$6*LN('Read me'!$B$6/('Read me'!$B$6+L40))+3*LN(L40/('Read me'!$B$6+L40)))+EXP(GAMMALN(4+'Read me'!$B$6)-GAMMALN('Read me'!$B$6)-GAMMALN(4+1)+'Read me'!$B$6*LN('Read me'!$B$6/('Read me'!$B$6+L40))+4*LN(L40/('Read me'!$B$6+L40)))),"") | N40: 0 | O40: =IFERROR(1/M40,"") | Q40: =IF(P40="","",P40*M40-1) | R40: =IF(Q40="","awaiting price",IF(Q40>='Read me'!$B$7,"BET",IF(Q40>=0,"thin","no bet")))
...

Sheet Mismatches
A1: Date | B1: League | C1: Fixture | D1: Team | E1: Side | F1: Bet | G1: Team/g | H1: Opp conc/g | I1: λ | J1: Run | K1: Prob | L1: Void | M1: Fair | N1: Book | O1: EV | P1: Verdict
A2: 46297 | B2: Brazil Série A | C2: Sao Paulo v Santos | D2: Sao Paulo | E2: Home | F2: 6+ team corners | G2: 8.6 | H2: 5.9 | I2: 7.44 | J2: 7 | K2: =IFERROR(1-(EXP(GAMMALN(0+'Read me'!$B$6)-GAMMALN('Read me'!$B$6)-GAMMALN(0+1)+'Read me'!$B$6*LN('Read me'!$B$6/('Read me'!$B$6+I2))+0*LN(I2/('Read me'!$B$6+I2)))+EXP(GAMMALN(1+'Read me'!$B$6)-GAMMALN('Read me'!$B$6)-GAMMALN(1+1)+'Read me'!$B$6*LN('Read me'!$B$6/('Read me'!$B$6+I2))+1*LN(I2/('Read me'!$B$6+I2)))+EXP(GAMMALN(2+'Read me'!$B$6)-GAMMALN('Read me'!$B$6)-GAMMALN(2+1)+'Read me'!$B$6*LN('Read me'!$B$6/('Read me'!$B$6+I2))+2*LN(I2/('Read me'!$B$6+I2)))+EXP(GAMMALN(3+'Read me'!$B$6)-GAMMALN('Read me'!$B$6)-GAMMALN(3+1)+'Read me'!$B$6*LN('Read me'!$B$6/('Read me'!$B$6+I2))+3*LN(I2/('Read me'!$B$6+I2)))+EXP(GAMMALN(4+'Read me'!$B$6)-GAMMALN('Read me'!$B$6)-GAMMALN(4+1)+'Read me'!$B$6*LN('Read me'!$B$6/('Read me'!$B$6+I2))+4*LN(I2/('Read me'!$B$6+I2)))+EXP(GAMMALN(5+'Read me'!$B$6)-GAMMALN('Read me'!$B$6)-GAMMALN(5+1)+'Read me'!$B$6*LN('Read me'!$B$6/('Read me'!$B$6+I2))+5*LN(I2/('Read me'!$B$6+I2)))),"") | L2: 0 | M2: =IFERROR(1/K2,"") | O2: =IF(N2="","",N2*K2-1) | P2: =IF(O2="","awaiting price",IF(O2>='Read me'!$B$7,"BET",IF(O2>=0,"thin","no bet")))
A3: 46297 | B3: Brazil Série B | C3: Novorizontino v Goias | D3: Novorizontino | E3: Home | F3: 6+ team corners | G3: 8 | H3: 5.9 | I3: 7.32 | J3: 13 | K3: =IFERROR(1-(EXP(GAMMALN(0+'Read me'!$B$6)-GAMMALN('Read me'!$B$6)-GAMMALN(0+1)+'Read me'!$B$6*LN('Read me'!$B$6/('Read me'!$B$6+I3))+0*LN(I3/('Read me'!$B$6+I3)))+EXP(GAMMALN(1+'Read me'!$B$6)-GAMMALN('Read me'!$B$6)-GAMMALN(1+1)+'Read me'!$B$6*LN('Read me'!$B$6/('Read me'!$B$6+I3))+1*LN(I3/('Read me'!$B$6+I3)))+EXP(GAMMALN(2+'Read me'!$B$6)-GAMMALN('Read me'!$B$6)-GAMMALN(2+1)+'Read me'!$B$6*LN('Read me'!$B$6/('Read me'!$B$6+I3))+2*LN(I3/('Read me'!$B$6+I3)))+EXP(GAMMALN(3+'Read me'!$B$6)-GAMMALN('Read me'!$B$6)-GAMMALN(3+1)+'Read me'!$B$6*LN('Read me'!$B$6/('Read me'!$B$6+I3))+3*LN(I3/('Read me'!$B$6+I3)))+EXP(GAMMALN(4+'Read me'!$B$6)-GAMMALN('Read me'!$B$6)-GAMMALN(4+1)+'Read me'!$B$6*LN('Read me'!$B$6/('Read me'!$B$6+I3))+4*LN(I3/('Read me'!$B$6+I3)))+EXP(GAMMALN(5+'Read me'!$B$6)-GAMMALN('Read me'!$B$6)-GAMMALN(5+1)+'Read me'!$B$6*LN('Read me'!$B$6/('Read me'!$B$6+I3))+5*LN(I3/('Read me'!$B$6+I3)))),"") | L3: 0 | M3: =IFERROR(1/K3,"") | O3: =IF(N3="","",N3*K3-1) | P3: =IF(O3="","awaiting price",IF(O3>='Read me'!$B$7,"BET",IF(O3>=0,"thin","no bet")))
A4: 46298 | B4: Netherlands Eerste Divisie | C4: FC OSS v MVV | D4: FC OSS | E4: Home | F4: 6+ team corners | G4: 5.56 | H4: 8.78 | I4: 7.15 | K4: =IFERROR(1-(EXP(GAMMALN(0+'Read me'!$B$6)-GAMMALN('Read me'!$B$6)-GAMMALN(0+1)+'Read me'!$B$6*LN('Read me'!$B$6/('Read me'!$B$6+I4))+0*LN(I4/('Read me'!$B$6+I4)))+EXP(GAMMALN(1+'Read me'!$B$6)-GAMMALN('Read me'!$B$6)-GAMMALN(1+1)+'Read me'!$B$6*LN('Read me'!$B$6/('Read me'!$B$6+I4))+1*LN(I4/('Read me'!$B$6+I4)))+EXP(GAMMALN(2+'Read me'!$B$6)-GAMMALN('Read me'!$B$6)-GAMMALN(2+1)+'Read me'!$B$6*LN('Read me'!$B$6/('Read me'!$B$6+I4))+2*LN(I4/('Read me'!$B$6+I4)))+EXP(GAMMALN(3+'Read me'!$B$6)-GAMMALN('Read me'!$B$6)-GAMMALN(3+1)+'Read me'!$B$6*LN('Read me'!$B$6/('Read me'!$B$6+I4))+3*LN(I4/('Read me'!$B$6+I4)))+EXP(GAMMALN(4+'Read me'!$B$6)-GAMMALN('Read me'!$B$6)-GAMMALN(4+1)+'Read me'!$B$6*LN('Read me'!$B$6/('Read me'!$B$6+I4))+4*LN(I4/('Read me'!$B$6+I4)))+EXP(GAMMALN(5+'Read me'!$B$6)-GAMMALN('Read me'!$B$6)-GAMMALN(5+1)+'Read me'!$B$6*LN('Read me'!$B$6/('Read me'!$B$6+I4))+5*LN(I4/('Read me'!$B$6+I4)))),"") | L4: 0 | M4: =IFERROR(1/K4,"") | O4: =IF(N4="","",N4*K4-1) | P4: =IF(O4="","awaiting price",IF(O4>='Read me'!$B$7,"BET",IF(O4>=0,"thin","no bet")))
